Workbook

Sheet Sheet1
A1: ໂລໂກ້ | G1: Logo Company
A2: ບໍລິສັດ………….. | G2: BCEL-KT Securities Co.,Ltd
A3: ເບີໂທ..……………. | G3: Tel: , Fax:
B4: ໃບລາຍງານກະແສເງິນສົດ | H4: Cash flow statment
B5: ປະຈຳປີ............... | H5: Yearly:...............
B6: ຫົວໜ່ວຍ: 1.000.000ກີບ | H6: Unit: 1.000.000 Lak
A7: ລຳດັບ | B7: ລາຍການ | C7: ເອກະສານຊ້ອນທ້າຍ | D7: ຈຳນວນເງິນ | G7: No | H7: Descriptions | I7: Note | J7: Amount
D8: ປີນີ້ | E8: ປີກ່ອນ | J8: This Year | K8: Last Year
A9: I | B9: ກະແສເງິນສົດຈາກກິດຈະກຳການດຳເນີນງານ | G9: I | H9: Cash flows from operating activities
B10: 1. ​ກໍາໄລ ຫຼື ຂາດທຶນສຸດທິກ່ອນອາກອນ | D10: 0 | E10: 0 | H10: 1. ​Net profit before tax for the period | J10: 0 | K10: 0
B11: 2. ລາຍການປັບປຸງຍອດກຳໄລ ຫຼື ຍອດຂາດທຶນເປັນເງິນສົດຮັບ-ຈ່າຍ | D11: =+D12+D13+D14+D15+D16+D17 -> 0 | E11: =+E12+E13+E14+E15+E16+E17 -> 0 | H11: 2. Adjustments to reconcile net profit to | J11: =+J12+J13+J14+J15+J16+J17 -> 0 | K11: =+K12+K13+K14+K15+K16+K17 -> 0
B12: 2.1. ຄ່າຫຼຸ້ຍຫ້ຽນ ແລະ ຄ່າເສື່ອມມູນຄ່າສຸດທິຂອງຊັບສົມບັດຄົງທີ່ມີຕົວຕົນ ແລະ ບໍ່ມີຕົວຕົນ | D12: 0 | E12: 0 | H12: 2.1. Depreciation | J12: 0 | K12: 0
B13: 2.2. ຄ່າເສື່ອມມູນຄ່າສຸດທິຂອງເງິນລົງທຶນໃນຫຼັກຊັບ ແລະ ລາຍການອື່ນໆ | D13: 0 | E13: 0 | H13: 2.2. Amortization | J13: 0 | K13: 0
B14: 2.3. ຂາດທຶນຈາກການຂາຍຊັບສົມບັດຄົງທີ່ | D14: 0 | E14: 0 | H14: 2.3. Loss on Disposal | J14: 0 | K14: 0
B15: 2.4. ກຳໄລຈາກການຂາຍຊັບສົມບັດຄົງທີ່ | D15: 0 | E15: 0 | H15: 2.4. Gain on Disposal | J15: 0 | K15: 0
B16: 2.5. ສ່ວນປ່ຽນແປງໃນລາຍການດອກເບ້ຍ ແລະ ລາຍຮັບອື່ນໆຄ້າງຮັບ | D16: 0 | E16: 0 | H16: 2.5. Unrealized (gain) loss on investment | J16: 0 | K16: 0
B17: 2.6. ສ່ວນປ່ຽນແປງໃນລາຍການດອກເບ້ຍ ແລະ ລາຍຈ່າຍອື່ນໆຄ້າງຈ່າຍ | D17: 0 | E17: 0 | H17: 2.6. Unrealized gain(loss) on exchange rate | J17: 0 | K17: 0
B18: ກ. ກະແສເງິນສົດສຸດທິຈາກກິດຈະກຳການດຳເນີນງານກ່ອນການປ່ຽນແປງໃນລາຍການຊັບສິນ ແລະ ໜີ້ສິນໝູນວຽນ | D18: =+D10+D11 -> 0 | E18: =+E10+E11 -> 0 | H18: A. Net loss from operating activities before changes in operating assets and liabilities | J18: =+J10+J11 -> 0 | K18: =+K10+K11 -> 0
B19: 3. ການປ່ຽນແປງ(ເພີ່ມຂຶ້ນ ຫຼື ຫຼຸດລົງ) ໃນລາຍການຊັບສິນໝູນວຽນ | D19: =+D20+D21+D22+D23+D24+D25+D26+D27 -> 0 | E19: =+E20+E21+E22+E23+E24+E25+E26+E27 -> 0 | H19: 3. Increase/Decrease in operating assets:- | J19: =+J20+J21+J22+J23+J24+J25+J26+J27 -> 0 | K19: =+K20+K21+K22+K23+K24+K25+K26+K27 -> 0
B20: 3.1. ເງິນຝາກທະນາຄານ ແລະ ສະຖາບັນການເງິນ | D20: 0 | E20: 0 | H20: 3.1. Deposit with banks and financial institutions | J20: 0 | K20: 0
B21: 3.2. ເງິນລົງທຶນໄລຍະສັ້ນ | D21: 0 | E21: 0 | H21: 3.2. Shorterm Investement "Investment in securities" | J21: 0 | K21: 0
B22: 3.3. ໜີ້ຕ້ອງຮັບທາງການຄ້າ | D22: 0 | E22: 0 | H22: 3.3. A/R on business | J22: 0 | K22: 0
B23: 3.4. ໜີ້ຕ້ອງຮັບທາງທຸລະກຳຫຼັກຊັບ | D23: 0 | E23: 0 | H23: 3.4. A/R Securities on Business | J23: 0 | K23: 0
B24: 3.5. ໜີ້ຕ້ອງຮັບລະຫວ່າງບໍລິສັດໃນກຸ່ມ | D24: 0 | E24: 0 | H24: 3.5. A/R clearing house | J24: 0 | K24: 0
B25: 3.6. ໜີ້ຕ້ອງຮັບອື່ນໆ | D25: 0 | E25: 0 | H25: 3.6. Other account receivable | J25: 0 | K25: 0
B26: 3.7. ເຄື່ອງໃນສາງ | D26: 0 | E26: 0 | H26: 3.7. Inventory | J26: 0 | K26: 0
B27: 3.8. ຊັບສິນໝູນວຽນອື່ນໆ | D27: 0 | E27: 0 | H27: 3.8. Other current assets | J27: 0 | K27: 0
B28: ຂ. ກະແສເງິນສົດສຸດທິຈາກການປ່ຽນແປງໃນຊັບສິນໝູນວຽນ | D28: =+D19 -> 0 | E28: =+E19 -> 0 | H28: B. Net Cash flow statement in operating assets | J28: =+J19 -> 0 | K28: =+K19 -> 0
B29: 4. ການປ່ຽນແປງ(ເພີ່ມຂຶ້ນ ຫຼື ຫຼຸດລົງ) ໃນລາຍການໜີ້ສິນໝູນວຽນ | D29: =+D30+D31+D32+D33+D34+D35 -> 0 | E29: =+E30+E31+E32+E33+E34+E35 -> 0 | H29: 4. Increase/Decrease in operating liabilities:- | J29: =+J30+J31+J32+J33+J34+J35 -> 0 | K29: =+K30+K31+K32+K33+K34+K35 -> 0
B30: 4.1. ໜີ້ຕ້ອງສົ່ງທາງການຄ້າ | D30: 0 | E30: 0 | H30: 4.1. A/P on business | J30: 0 | K30: 0
B31: 4.2. ໜີ້ຕ້ອງສົ່ງທາງທຸລະກຳຫຼັກຊັບ | D31: 0 | E31: 0 | H31: 4.2. A/P Securities on Business | J31: 0 | K31: 0
B32: 4.3. ໜີ້ຕ້ອງສົ່ງລະຫວ່າງບໍລິສັດໃນກຸ່ມ | D32: 0 | E32: 0 | H32: 4.3. A/R clearing house | J32: 0 | K32: 0
B33: 4.4. ອາກອນກຳໄລຄ້າງຈ່າຍ | D33: 0 | E33: 0 | H33: 4.4. Accrued corporate income tax | J33: 0 | K33: 0
B34: 4.5. ໜີ້ຕ້ອງສົ່ງອື່ນໆ | D34: 0 | E34: 0 | H34: 4.5. Other liabilities | J34: 0 | K34: 0
B35: 4.6. ໜີ້ສິນໝູນວຽນອື່ນໆ | D35: 0 | E35: 0 | H35: 4.6. Subscription payable | J35: 0 | K35: 0
B36: ຄ. ກະແສເງິນສົດສຸດທິຈາກການປ່ຽນແປງໃນໜີ້ສິນໝູນວຽນ | D36: =+D29 -> 0 | E36: =+E29 -> 0 | H36: C. Net Cash flow statement in operating Liabilities | J36: =+J29 -> 0 | K36: =+K29 -> 0
B37: ກະແສເງິນສົດສຸດທິຈາກກິດຈະກຳດຳເນີນງານ | D37: =+D18+D28+D36 -> 0 | E37: =+E18+E28+E36 -> 0 | H37: Net Cash flows from operating activities | J37: =+J18+J28+J36 -> 0 | K37: =+K18+K28+K36 -> 0
A38: II | B38: ​ກະແສເງິນສົດຈາກກິດຈະກໍາລົງທຶນ | G38: II | H38: Cash flows from investing activities
B39: 1. ສ່ວນເພີ່ມຫຼືຫຼຸດໃນລາຍການເງິນລົງທຶນໄລຍະຍາວ | D39: 0 | E39: 0 | H39: 1. Increase/Decrease on long term investment | J39: 0 | K39: 0
B40: 2. ສ່ວນເພີ່ມຫຼືຫຼຸດໃນລາຍໜີ້ຕ້ອງຮັບໄລຍະຍາວ ແລະ ຊັບສິນໄລຍະຍາວອື່ນໆ | D40: 0 | E40: 0 | H40: 2. Increase/Decrease A/R and other assets on long term investment | J40: 0 | K40: 0
...

Sheet Sheet2
A1: ໂລໂກ້
A2: ບໍລິສັດ…………..
A3: ເບີໂທ..…………….
B4: ໃບລາຍງານກະແສເງິນສົດ
B5: ປະຈຳປີ...............
B6: ຫົວໜ່ວຍ: 1.000.000ກີບ
A7: ລຳດັບ | B7: ລາຍການ
B8: ລາຍການ | C8: ເຄື່ອງໝາຍ | D8: ເລກບັນຊີ
A9: I | B9: ກະແສເງິນສົດຈາກກິດຈະກຳການດຳເນີນງານ
B10: 1. ​ກໍາໄລ ຫຼື ຂາດທຶນສຸດທິກ່ອນອາກອນ | D10: ຍອດເຫຼືອບັນຊີ 3901
B11: 2. ລາຍການປັບປຸງຍອດກຳໄລ ຫຼື ຍອດຂາດທຶນເປັນເງິນສົດຮັບ-ຈ່າຍ
B12: 2.1. ຄ່າຫຼຸ້ຍຫ້ຽນ ແລະ ຄ່າເສື່ອມມູນຄ່າສຸດທິຂອງຊັບສົມບັດຄົງທີ່ມີຕົວຕົນ ແລະ ບໍ່ມີຕົວຕົນ | C12: +/- | D12: ບ/ຊ 148
B13: 2.2. ຄ່າເສື່ອມມູນຄ່າສຸດທິຂອງເງິນລົງທຶນໃນຫຼັກຊັບ ແລະ ລາຍການອື່ນໆ | C13: +/- | D13: ບ/ຊ 1319+1419+1199111+1199121+1199131+1199141+1199211+1199231+1199241+
D14: 1299111+1299121+1299131+1299141+1299211+1299221+1299231+1199241+1199112+
D15: 1199113+1199122+1199123+1199132+1199133+1199142+1199143+1199212+1199213+
D16: 1199222+1199223+1199232+1199233+1199242+1199243+1299112+1299113+1299122+
D17: 1299123+1299132+1299133+1299142+1299143+1299212+1299222+1299232+1299142
B18: 2.3. ຂາດທຶນຈາກການຂາຍຊັບສົມບັດຄົງທີ່ | C18: + | D18: ບ/ຊ 4506+410416
B19: 2.4. ກຳໄລຈາກການຂາຍຊັບສົມບັດຄົງທີ່ | C19: - | D19: ບ/ຊ 5506+510416+510426
B20: 2.5. ສ່ວນປ່ຽນແປງໃນລາຍການດອກເບ້ຍ ແລະ ລາຍຮັບອື່ນໆຄ້າງຮັບ | D20: What account No ??????? | E20: None
B21: 2.6. ສ່ວນປ່ຽນແປງໃນລາຍການດອກເບ້ຍ ແລະ ລາຍຈ່າຍອື່ນໆຄ້າງຈ່າຍ | D21: What account No ??????? | E21: None
B22: ກ. ກະແສເງິນສົດສຸດທິຈາກກິດຈະກຳການດຳເນີນງານກ່ອນການປ່ຽນແປງໃນລາຍການຊັບສິນ ແລະ ໜີ້ສິນໝູນວຽນ | D22: ກ=3(Item 3.1 to Item 3.8)
B24: 3. ການປ່ຽນແປງ(ເພີ່ມຂຶ້ນ ຫຼື ຫຼຸດລົງ) ໃນລາຍການຊັບສິນໝູນວຽນ
B25: 3.1. ເງິນຝາກທະນາຄານ ແລະ ສະຖາບັນການເງິນ | C25: -/+ | D25: ບ/ຊ 1121+1131+1122
B26: 3.2. ເງິນລົງທຶນໄລຍະສັ້ນ | C26: -/+ | D26: ບ/ຊ 13011+13021+13025+13026+(130311-130391)+(130312-130392)+130351+130352+1311
B27: 3.3. ໜີ້ຕ້ອງຮັບທາງການຄ້າ | C27: -/+ | D27: ບ/ຊ 12011
B28: 3.4. ໜີ້ຕ້ອງຮັບທາງທຸລະກຳຫຼັກຊັບ | C28: -/+ | D28: ບ/ຊ 120611+12311+123151+1241+1261
B29: 3.5. ໜີ້ຕ້ອງຮັບລະຫວ່າງບໍລິສັດໃນກຸ່ມ | C29: -/+ | D29: ບ/ຊ 12111+121121
B30: 3.6. ໜີ້ຕ້ອງຮັບອື່ນໆ | C30: -/+ | D30: ບ/ຊ 113211+1132121+113221+1132221+119111+119121+119131+119141+119211+
D31: 119221+119231+119241+1207+129111+12921+129131+129141+129211+129221+129231+
D32: 129241
B33: 3.7. ເຄື່ອງໃນສາງ | C33: -/+ | D33: ບ/ຊ 1371+1373+1376+1378-1379
B34: 3.8. ຊັບສິນໝູນວຽນອື່ນໆ | C34: -/+ | D34: ບ/ຊ 1361+1362+138+1138
B35: ຂ. ກະແສເງິນສົດສຸດທິຈາກການປ່ຽນແປງໃນຊັບສິນໝູນວຽນ
B36: 4. ການປ່ຽນແປງ(ເພີ່ມຂຶ້ນ ຫຼື ຫຼຸດລົງ) ໃນລາຍການໜີ້ສິນໝູນວຽນ
B37: 4.1. ໜີ້ຕ້ອງສົ່ງທາງການຄ້າ | C37: +/- | D37: ບ/ຊ 2127+2137+21472167+2237+2247+2267+23017+23027+23317+23327+23357+23367+
D38: 2347+2367
B39: 4.2. ໜີ້ຕ້ອງສົ່ງທາງທຸລະກຳຫຼັກຊັບ | C39: +/- | D39: ບ/ຊ 23011+23021+23022+231+23311+23321+23351+2341+2342+2343+2344+2346
B40: 4.3. ໜີ້ຕ້ອງສົ່ງລະຫວ່າງບໍລິສັດໃນກຸ່ມ | C40: + | D40: ບ/ຊ 22111+22121
B41: 4.4. ອາກອນກຳໄລຄ້າງຈ່າຍ | C41: +/- | D41: ບ/ຊ 236111
...

Sheet FinalFormwFx2
A1: ໂລໂກ້
A2: ບໍລິສັດ…………..
A3: ເບີໂທ..…………….
B4: ໃບລາຍງານກະແສເງິນສົດ
B5: ປະຈຳປີ...............
B6: ຫົວໜ່ວຍ: 1.000.000ກີບ
A7: ລຳດັບ | B7: ລາຍການ
B8: ລາຍການ | C8: ເຄື່ອງໝາຍ | D8: ເລກບັນຊີ
A9: I | B9: ກະແສເງິນສົດຈາກກິດຈະກຳການດຳເນີນງານ
B10: 1. ​ກໍາໄລ ຫຼື ຂາດທຶນສຸດທິກ່ອນອາກອນ | D10: ຍອດເຫຼືອບັນຊີ 3901
B11: 2. ລາຍການປັບປຸງຍອດກຳໄລ ຫຼື ຍອດຂາດທຶນເປັນເງິນສົດຮັບ-ຈ່າຍ
B12: 2.1. ຄ່າຫຼຸ້ຍຫ້ຽນ ແລະ ຄ່າເສື່ອມມູນຄ່າສຸດທິຂອງຊັບສົມບັດຄົງທີ່ມີຕົວຕົນ ແລະ ບໍ່ມີຕົວຕົນ | C12: +/- | D12: ບ/ຊ 148
B13: 2.2. ຄ່າເສື່ອມມູນຄ່າສຸດທິຂອງເງິນລົງທຶນໃນຫຼັກຊັບ ແລະ ລາຍການອື່ນໆ | C13: +/- | D13: ບ/ຊ 1319+1419+1199111+1199121+1199131+1199141+1199211+1199231+1199241+
D14: 1299111+1299121+1299131+1299141+1299211+1299221+1299231+1199241+1199112+
D15: 1199113+1199122+1199123+1199132+1199133+1199142+1199143+1199212+1199213+
D16: 1199222+1199223+1199232+1199233+1199242+1199243+1299112+1299113+1299122+
D17: 1299123+1299132+1299133+1299142+1299143+1299212+1299222+1299232+1299142
B18: 2.3. ຂາດທຶນຈາກການຂາຍຊັບສົມບັດຄົງທີ່ | C18: + | D18: ບ/ຊ 4506+410416
B19: 2.4. ກຳໄລຈາກການຂາຍຊັບສົມບັດຄົງທີ່ | C19: - | D19: ບ/ຊ 5506+510416+510426
B20: 2.5. ສ່ວນປ່ຽນແປງໃນລາຍການດອກເບ້ຍ ແລະ ລາຍຮັບອື່ນໆຄ້າງຮັບ
B21: 2.6. ສ່ວນປ່ຽນແປງໃນລາຍການດອກເບ້ຍ ແລະ ລາຍຈ່າຍອື່ນໆຄ້າງຈ່າຍ
B22: ກ. ກະແສເງິນສົດສຸດທິຈາກກິດຈະກຳການດຳເນີນງານກ່ອນການປ່ຽນແປງໃນລາຍການຊັບສິນ ແລະ ໜີ້ສິນໝູນວຽນ
B24: 3. ການປ່ຽນແປງ(ເພີ່ມຂຶ້ນ ຫຼື ຫຼຸດລົງ) ໃນລາຍການຊັບສິນໝູນວຽນ
B25: 3.1. ເງິນຝາກທະນາຄານ ແລະ ສະຖາບັນການເງິນ | C25: -/+ | D25: ບ/ຊ 1121+1131+1122
B26: 3.2. ເງິນລົງທຶນໄລຍະສັ້ນ | C26: -/+ | D26: ບ/ຊ 13011+13021+13025+13026+(130311-130391)+(130312-130392)+130351+130352+1311
B27: 3.3. ໜີ້ຕ້ອງຮັບທາງການຄ້າ | C27: -/+ | D27: ບ/ຊ 12011
B28: 3.4. ໜີ້ຕ້ອງຮັບທາງທຸລະກຳຫຼັກຊັບ | C28: -/+ | D28: ບ/ຊ 120611+12311+123151+1241+1261
B29: 3.5. ໜີ້ຕ້ອງຮັບລະຫວ່າງບໍລິສັດໃນກຸ່ມ | C29: -/+ | D29: ບ/ຊ 12111+121121
B30: 3.6. ໜີ້ຕ້ອງຮັບອື່ນໆ | C30: -/+ | D30: ບ/ຊ 113211+1132121+113221+1132221+119111+119121+119131+119141+119211+
D31: 119221+119231+119241+1207+129111+12921+129131+129141+129211+129221+129231+
D32: 129241
B33: 3.7. ເຄື່ອງໃນສາງ | C33: -/+ | D33: ບ/ຊ 1371+1373+1376+1378-1379
B34: 3.8. ຊັບສິນໝູນວຽນອື່ນໆ | C34: -/+ | D34: ບ/ຊ 1361+1362+138+1138+1360000 | E34: ????????????
B35: ຂ. ກະແສເງິນສົດສຸດທິຈາກການປ່ຽນແປງໃນຊັບສິນໝູນວຽນ
B36: 4. ການປ່ຽນແປງ(ເພີ່ມຂຶ້ນ ຫຼື ຫຼຸດລົງ) ໃນລາຍການໜີ້ສິນໝູນວຽນ
B37: 4.1. ໜີ້ຕ້ອງສົ່ງທາງການຄ້າ | C37: +/- | D37: ບ/ຊ 2127+2137+21472167+2237+2247+2267+23017+23027+23317+23327+23357+23367+
D38: 2347+2367
B39: 4.2. ໜີ້ຕ້ອງສົ່ງທາງທຸລະກຳຫຼັກຊັບ | C39: +/- | D39: ບ/ຊ 23011+23021+23022+231+23311+23321+23351+2341+2342+2343+2344+2346
B40: 4.3. ໜີ້ຕ້ອງສົ່ງລະຫວ່າງບໍລິສັດໃນກຸ່ມ | C40: + | D40: ບ/ຊ 22111+22121
B41: 4.4. ອາກອນກຳໄລຄ້າງຈ່າຍ | C41: +/- | D41: ບ/ຊ 236111
...

Sheet FinalForm
A1: ໂລໂກ້
A2: ບໍລິສັດ…………..
A3: ເບີໂທ..…………….
B4: ໃບລາຍງານກະແສເງິນສົດ
B5: ປະຈຳປີ: 2012 | G5: Note for A/C
B6: ຫົວໜ່ວຍ: 1.000.000ກີບ
A7: ລຳດັບ | B7: ລາຍການ | C7: ເອກະສານຊ້ອນທ້າຍ | D7: ຈຳນວນເງິນ
D8: ປີນີ້ | E8: ປີກ່ອນ
A9: I | B9: ກະແສເງິນສົດຈາກກິດຈະກຳການດຳເນີນງານ
B10: 1. ​ກໍາໄລ ຫຼື ຂາດທຶນສຸດທິກ່ອນອາກອນ | D10: =SUM('TB 2012'!J86:J172)/1000 -> 3764215.6 | E10: 0 | F10: Cr-Dr " Movement of 4-5 "+ A/C: 49
B11: 2. ລາຍການປັບປຸງຍອດກຳໄລ ຫຼື ຍອດຂາດທຶນເປັນເງິນສົດຮັບ-ຈ່າຍ | D11: =+D12+D13+D14+D15+D16+D17 -> 418699.01 | E11: =+E12+E13+E14+E15+E16+E17 -> 0
B12: 2.1. ຄ່າຫຼຸ້ຍຫ້ຽນ ແລະ ຄ່າເສື່ອມມູນຄ່າສຸດທິຂອງຊັບສົມບັດຄົງທີ່ມີຕົວຕົນ ແລະ ບໍ່ມີຕົວຕົນ | D12: =SUM('TB 2012'!J50:J56)/1000 -> 418699.01 | E12: 0 | G12: 1481
B13: 2.2. ຄ່າເສື່ອມມູນຄ່າສຸດທິຂອງເງິນລົງທຶນໃນຫຼັກຊັບ ແລະ ລາຍການອື່ນໆ | D13: 0 | E13: 0
B14: 2.3. ຂາດທຶນຈາກການຂາຍຊັບສົມບັດຄົງທີ່ | D14: 0 | E14: 0
B15: 2.4. ກຳໄລຈາກການຂາຍຊັບສົມບັດຄົງທີ່ | D15: 0 | E15: 0
B16: 2.5. ສ່ວນປ່ຽນແປງໃນລາຍການດອກເບ້ຍ ແລະ ລາຍຮັບອື່ນໆຄ້າງຮັບ | D16: 0 | E16: 0
B17: 2.6. ສ່ວນປ່ຽນແປງໃນລາຍການດອກເບ້ຍ ແລະ ລາຍຈ່າຍອື່ນໆຄ້າງຈ່າຍ | D17: 0 | E17: 0
B18: ກ. ກະແສເງິນສົດສຸດທິຈາກກິດຈະກຳການດຳເນີນງານກ່ອນການປ່ຽນແປງໃນລາຍການຊັບສິນ ແລະ ໜີ້ສິນໝູນວຽນ | D18: =+D10+D11 -> 4182914.6 | E18: =+E10+E11 -> 0 | G18: 1+2
B19: 3. ການປ່ຽນແປງ (ເພີ່ມຂຶ້ນ) ຫຼື ຫຼຸດລົງ ໃນລາຍການຊັບສິນໝູນວຽນ | D19: =+D20+D21+D22+D23+D24+D25+D26+D27 -> -21876577 | E19: =+E20+E21+E22+E23+E24+E25+E26+E27 -> 0
B20: 3.1. ເງິນຝາກທະນາຄານ ແລະ ສະຖາບັນການເງິນ | D20: =-SUM('TB 2012'!I6:I25)/1000 -> -20185460 | E20: 0 | G20: 1121+1131
B21: 3.2. ເງິນລົງທຶນໄລຍະສັ້ນ | D21: =-('TB 2012'!I33+'TB 2012'!I34)/1000 -> -434990.2 | E21: 0 | G21: 1302216+1302218
B22: 3.3. ໜີ້ຕ້ອງຮັບທາງການຄ້າ | D22: =-'TB 2012'!I30/1000 -> -54536.206 | E22: 0 | G22: 1201181
B23: 3.4. ໜີ້ຕ້ອງຮັບທາງທຸລະກຳຫຼັກຊັບ | D23: 0 | E23: 0 | G23: ບ/ຊ 120611+12311+123151+1241+1261
B24: 3.5. ໜີ້ຕ້ອງຮັບລະຫວ່າງບໍລິສັດໃນກຸ່ມ | D24: =-'TB 2012'!I31/1000 -> 23823.233 | E24: 0 | G24: 1211110
B25: 3.6. ໜີ້ຕ້ອງຮັບອື່ນໆ | D25: =-('TB 2012'!I26+'TB 2012'!I32)/1000 -> -1027703.1 | E25: 0 | G25: 1137111+1301720
B26: 3.7. ເຄື່ອງໃນສາງ | D26: 0 | E26: 0 | G26: ບ/ຊ 1371+1373+1376+1378-1379
B27: 3.8. ຊັບສິນໝູນວຽນອື່ນໆ | D27: =-SUM('TB 2012'!I35:I43)/1000-SUM('TB 2012'!I27:I29)/1000 -> -197710.1 | E27: 0 | G27: 1138100+1138810+1138830+1360000+1361100+1361300+1361500+1362100+1388110+1388120+1388170+1388180
B28: ຂ. ກະແສເງິນສົດສຸດທິຈາກການປ່ຽນແປງໃນຊັບສິນໝູນວຽນ | D28: =+D19 -> -21876577 | E28: =+E19 -> 0
B29: 4. ການປ່ຽນແປງ ເພີ່ມຂຶ້ນ ຫຼື (ຫຼຸດລົງ) ໃນລາຍການໜີ້ສິນໝູນວຽນ | D29: =+D30+D31+D32+D33+D34+D35 -> 17872192 | E29: =+E30+E31+E32+E33+E34+E35 -> 0
B30: 4.1. ໜີ້ຕ້ອງສົ່ງທາງການຄ້າ | D30: 0 | E30: 0
B31: 4.2. ໜີ້ຕ້ອງສົ່ງທາງທຸລະກຳຫຼັກຊັບ | D31: =SUM('TB 2012'!J59:J62)/1000 -> 15911349 | E31: 0 | G31: 2344100+2344200+2344600+2344700
B32: 4.3. ໜີ້ຕ້ອງສົ່ງລະຫວ່າງບໍລິສັດໃນກຸ່ມ | D32: ='TB 2012'!J57/1000 -> 53391.814 | E32: 0 | G32: 2211110
B33: 4.4. ອາກອນກຳໄລຄ້າງຈ່າຍ | D33: ='TB 2012'!J63/1000 -> 1455561.6 | E33: 0 | G33: 2361110
B34: 4.5. ໜີ້ຕ້ອງສົ່ງອື່ນໆ | D34: =SUM('TB 2012'!J64:J72)/1000 -> 134141.94 | E34: 0 | G34: 2361120+2361130+2361140+2361410+2361420+2361430+2361440+2361830+2361831
B35: 4.6. ໜີ້ສິນໝູນວຽນອື່ນໆ | D35: =SUM('TB 2012'!J73:J75)/1000 -> 317746.77 | E35: 0 | G35: 2363682+2363683+2363684
B36: ຄ. ກະແສເງິນສົດສຸດທິຈາກການປ່ຽນແປງໃນໜີ້ສິນໝູນວຽນ | D36: =+D29 -> 17872192 | E36: =+E29 -> 0 | F36: ok for the formula
B37: ກະແສເງິນສົດສຸດທິຈາກກິດຈະກຳດຳເນີນງານ | D37: =+D18+D28+D36 -> 178529.32 | E37: =+E18+E28+E36 -> 0
A38: II | B38: ​ກະແສເງິນສົດຈາກກິດຈະກໍາລົງທຶນ
B39: 1. ສ່ວນ (ເພີ່ມຂຶ້ນ) ຫຼື ຫຼຸດລົງ ໃນລາຍການເງິນລົງທຶນໄລຍະຍາວ | D39: 0 | E39: 0
B40: 2. ສ່ວນ (ເພີ່ມຂຶ້ນ) ຫຼື ຫຼຸດລົງ ໃນລາຍໜີ້ຕ້ອງຮັບໄລຍະຍາວ ແລະ ຊັບສິນໄລຍະຍາວອື່ນໆ | D40: 0 | E40: 0
...

Sheet TB 2012
A1: ສາທາລະນະລັດ ປະຊາທິປະໄຕ ປະຊາຊົນລາວ | B1: ສັນຕິພາບ ເອກະລາດ ປະຊາທິປະໄຕ ເອກະພາບ ວັດທະນາຖາວອນ | F1: 2012
A2: ບໍລິສັດຫຼັກຊັບ ທຄຕລ-ກທ ຈຳກັດ_x000D_ ຊັ້ນ7, ຕຶກຕະຫຼາກຫຼັກຊັບລາວ, ຖະໜົນກຳແພງເມືອງ_x000D_ +856-21-265477+856-21-265488
C3: Opening | E3: Movement | G3: Balance | I3: Change
C4: ໜີ້ | D4: ມີ | E4: ໜີ້ | F4: ມີ | G4: ໜີ້ | H4: ມີ | I4: ໜີ້ | J4: ມີ
A5: 1101100 | B5: ເງິນສົດໃນຄັງ " HO " ກີບ | C5: 10000000 | D5: 0 | E5: 1.4693651e+08 | F5: 1.5246851e+08 | G5: 4468000 | H5: 0 | I5: =G5-C5 -> -5532000 | L5: =+E5-F5 -> -5532000
A6: 1121110 | B6: ບັນຊີທຶນຈົດທະບຽນຂອງ ທຄຕລ-ກທ ຈຳກັດ ( ກີບ ) | C6: 7.2281614e+10 | D6: 0 | E6: 0 | F6: 70000010000 | G6: 2.2816035e+09 | H6: 0 | I6: =G6-C6 -> -70000010000 | L6: =+E6-F6 -> -70000010000
A7: 1131110 | B7: ບັນຊີກະແສລາຍວັນ ທຄຕລ: 010.0.11.00.24740 ( ກີບ ) | C7: 652607.74 | D7: 0 | E7: 2.6829711e+08 | F7: 268812113 | G7: 137607.24 | H7: 0 | I7: =G7-C7 -> -515000.5 | L7: =+E7-F7 -> -515000.5
A8: 1131111 | B8: ບັນຊີກະແສລາຍວັນ ທຄຕລ: 010.7.11.02.08233 ( ບາດ ) | C8: 713249.55 | D8: 0 | E8: 1196931.5 | F8: 121655.66 | G8: 1788525.4 | H8: 0 | I8: =G8-C8 -> 1075275.8 | L8: =+E8-F8 -> 1075275.8
A9: 1131112 | B9: ບັນຊີກະແສລາຍວັນ ທຄຕລ: 010.9.11.01.19243 ( ໂດລ່າ ) | C9: 1641620.4 | D9: 0 | E9: 69481101 | F9: 69528404 | G9: 1594317.1 | H9: 0 | I9: =G9-C9 -> -47303.28 | L9: =+E9-F9 -> -47303.28
A10: 1131113 | B10: ບັນຊີກະແສລາຍວັນ ທຄຕລ Proprietary AC: 010.4.19.00.00009 ( ກີບ ) | C10: 92595445 | D10: 0 | E10: 154946789255 | F10: 154744754910 | G10: 294629790 | H10: 0 | I10: =G10-C10 -> 202034345 | L10: =+E10-F10 -> 202034345
A11: 1131115 | B11: ບັນຊີກະແສລາຍວັນ ທຄຕລ Aggregate AC: 010.4.19.00.00010 ( ກີບ ) | C11: 39741098167 | D11: 0 | E11: 669329114813 | F11: 653419265157 | G11: 55650947823 | H11: 0 | I11: =G11-C11 -> 15909849656 | L11: =+E11-F11 -> 15909849656
A12: 1131116 | B12: ບັນຊີກະແສລາຍວັນ ທຄຕລ for ETL staff IPO AC: 010.9.00.00001 ( ກີບ ) | C12: 100000 | D12: 0 | E12: 0 | F12: 0 | G12: 100000 | H12: 0 | I12: =G12-C12 -> 0
A13: 1131117 | B13: ບັນຊີກະແສລາຍວັນ ທຄຕລ ສຳລັບການຈອງ RO EDL-Gen :010.8.19.00.00012 LAk | C13: 0 | D13: 0 | E13: 405151388000 | F13: 405151388000 | G13: 0 | H13: 0 | I13: =G13-C13 -> 0
A14: 1131119 | B14: ບັນຊີກະແສລາຍວັນ ທຄຕລ ສຳລັບການ​ຈອງ PO EDL: 010.5.19.00.00013 Lak | C14: 0 | D14: 0 | E14: 1.7653324e+10 | F14: 1.7653324e+10 | G14: 0 | H14: 0 | I14: =G14-C14 -> 0
A15: 1131120 | B15: ບັນຊີກະແສລາຍວັນ ທຄຕລ ສຳລັບການ​ຈອງ PO EDL: 010.4.19.01.00006 USD | C15: 0 | D15: 0 | E15: 1.7085271e+11 | F15: 1.7085271e+11 | G15: 0 | H15: 0 | I15: =G15-C15 -> 0 | L15: =+SUM(I5:I20) -> -4.4820072e+10 | M15: OK
A16: 1131121 | B16: ບັນຊີກະແສລາຍວັນ ເອຊີລີດາ 123359-1-1-101 | C16: 0 | D16: 0 | E16: 1000000 | F16: 0 | G16: 1000000 | H16: 0 | I16: =G16-C16 -> 1000000 | L16: =+L15-L21 -> 0
A17: 1131130 | B17: ບັນຊີຝາກປະຢັດທີ່ ທຄຕລ: 013.2.12.00.00036 ກີບ | C17: 2.2618014e+09 | D17: 0 | E17: 1.1798555e+11 | F17: 1.10998e+11 | G17: 9.2493495e+09 | H17: 0 | I17: =G17-C17 -> 6.9875481e+09
A18: 1131131 | B18: ບັນຊີຝາກປະຢັດທີ່ ທຄຕລ: 013.9.12.01.00001 ( ໂດລ່າ ) | C18: 8.9027339e+08 | D18: 0 | E18: 3.5927276e+10 | F18: 3.6787536e+10 | G18: 30012667 | H18: 0 | I18: =G18-C18 -> -8.6026073e+08 | L18: =+SUM(C5:C20) -> 1.1663937e+11 | M18: Cash for 2011
A19: 1131134 | B19: ບັນຊີຝາກປະຢັດທີ່ ທສກ: 0402.0.00.220130 ( ກີບ ) | C19: 1358879432 | D19: 0 | E19: 2110287566 | F19: 0 | G19: 3469166998 | H19: 0 | I19: =G19-C19 -> 2110287566 | L19: =+SUM(G5:G20) -> 7.1819297e+10 | M19: Cash for 2012
A20: 1131137 | B20: ບັນຊີຝາກປະຍັດ ທຄຕລ-ກທ ທີ່ ເອຊີລີດາ 123359-1-0-0101 ( ກີບ ) | C20: 0 | D20: 0 | E20: 3.5834499e+10 | F20: 35000000000 | G20: 8.3449851e+08 | H20: 0 | I20: =G20-C20 -> 8.3449851e+08
A21: 1131153 | B21: ບັນຊີຝາກມີກຳນົດທີ່ ທສກ: 0402.0402.00.2131315.47.00000003 ( ກີບ ) | C21: 20000000000 | D21: 0 | E21: 0 | F21: 0 | G21: 20000000000 | H21: 0 | I21: =G21-C21 -> 0 | L21: =+L19-L18 -> -4.4820072e+10 | M21: Change for the year
A22: 1131154 | B22: ບັນຊີຝາກມີກຳນົດທີ່ ທສກ: 0402.0402.00.2131315.47.00000004 ( ກີບ ) | C22: 0 | D22: 0 | E22: 25000000000 | F22: 0 | G22: 25000000000 | H22: 0 | I22: =G22-C22 -> 25000000000 | L22: =+L18 -> 1.1663937e+11 | M22: Cash and cash equarvalent for the last year / beginning for the year
A23: 1131156 | B23: ບັນຊີຝາກມີກຳນົດທີ່ Sacom Bank: 40.000006310.8 ( ກີບ ) | C23: 0 | D23: 0 | E23: 30000000000 | F23: 30000000000 | G23: 0 | H23: 0 | I23: =G23-C23 -> 0 | L23: =+SUM(L21:L22) -> 7.1819297e+10
A24: 1131159 | B24: ບັນຊີຝາກມີກຳນົດທີ່ ST Bank: 010.5.35.00.08899 ( ກີບ ) | C24: 0 | D24: 0 | E24: 5000000000 | F24: 0 | G24: 5000000000 | H24: 0 | I24: =G24-C24 -> 5000000000
A25: 1131162 | B25: ບັນຊີເງິນຝາກມີກຳນົດ ທີ່ ທະນາຄານ ເອຊີລີດາ ( ກີບ ) | C25: 0 | D25: 0 | E25: 35000000000 | F25: 0 | G25: 35000000000 | H25: 0 | I25: =G25-C25 -> 35000000000
A26: 1137111 | B26: ດອກເບ້ຍຝາກມີກຳນົດ ຄ້າງຮັບ 1 ປີລົງມາ | C26: 169863014 | D26: 0 | E26: 5824469182 | F26: 5.3326256e+09 | G26: 6.6170662e+08 | H26: 0 | I26: =G26-C26 -> 4.9184361e+08
A27: 1138100 | B27: ກອງທຶນປົກປ້ອງຄວາມສ່ຽງໃນການຊຳລະສະສາງ | C27: 136517614 | D27: 0 | E27: 18938509 | F27: 342 | G27: 155455781 | H27: 0 | I27: =G27-C27 -> 18938167
A28: 1138810 | B28: ເງິນມັດຈຳຄ່າເຊົ່າ | C28: 11888910 | D28: 0 | E28: 0 | F28: 0 | G28: 11888910 | H28: 0 | I28: =G28-C28 -> 0
A29: 1138830 | B29: ເງິນມັດຈຳອື່ນໆ | C29: 0 | D29: 0 | E29: 4449332 | F29: 4449332 | G29: 0 | H29: 0 | I29: =G29-C29 -> 0
A30: 1201181 | B30: ລູກໜີ້ຊື້ຫຼັກຊັບຕາມຄຳສັ່ງຊື້-ບັນຊີເງິນສົດ | C30: 4284683 | D30: 0 | E30: 23279067826 | F30: 23224531620 | G30: 58820889 | H30: 0 | I30: =G30-C30 -> 54536206
A31: 1211110 | B31: ລູກໜີ້ບັນຊີຊື້-ຂາຍຫຼັກຊັບລະຫວ່າງບ/ສ ກັບ LSX | C31: 23823233 | D31: 0 | E31: 5742141356 | F31: 5765964589 | G31: 0 | H31: 0 | I31: =G31-C31 -> -23823233
A32: 1301720 | B32: ຄ່າທີ່ປຶກສາຄ້າງຮັບ | C32: 0 | D32: 0 | E32: 1024442620 | F32: 488583100 | G32: 535859520 | H32: 0 | I32: =G32-C32 -> 535859520 | L32: =-SUM('TB 2012'!I35:I43)/1000-SUM('TB 2012'!I27:I29)/1000 -> -197710.1
A33: 1302216 | B33: ເງິນລົງທືນຊົ່ວຄາວຫຼັກຊັບ-ເພື່ອຄ້າ-Port Trading | C33: 117180970 | D33: 0 | E33: 5.5465994e+08 | F33: 197620970 | G33: 4.7421994e+08 | H33: 0 | I33: =G33-C33 -> 3.5703897e+08
A34: 1302218 | B34: ຄ່າປັບມູນຄ່າເງິນລົງທືນຊົ່ວຄາວຫຼັກຊັບ-ເພື່ອຄ້າ-Port trading | C34: 0 | D34: 37250970 | E34: 4.0190649e+08 | F34: 3.2395527e+08 | G34: 40700260 | H34: 0 | I34: =G34-C34+D34 -> 77951230 | L34: =+E34-F34 -> 77951230
A35: 1360000 | B35: ລູກໜີ້ອື່ນໆ | C35: 61100181 | D35: 0 | E35: 4846066 | F35: 59977664 | G35: 5968583 | H35: 0 | I35: =G35-C35 -> -55131598 | L35: =+E35-F35 -> -55131598
A36: 1361100 | B36: ອາກອນກຳໄລມອບລ່ວງໜ້າ | C36: 27761356 | D36: 0 | E36: 99581906 | F36: 1.2734326e+08 | G36: 0 | H36: 0 | I36: =G36-C36 -> -27761356 | L36: =+E36-F36 -> -27761356
A37: 1361300 | B37: ອາກອນອື່ນໆທີ່ຕ້ອງຮັບຄືນ | C37: 27382364 | D37: 0 | E37: 6845600 | F37: 34227964 | G37: 0 | H37: 4.7683716e-09 | I37: =G37-C37 -> -27382364 | L37: =+E37-F37 -> -27382364
A38: 1361500 | B38: ລູນໜີ້ ເຄທີຂີມີໂກ້ ຈຳກັດ | C38: 0 | D38: 0 | E38: 94848000 | F38: 94848000 | G38: 0 | H38: 0 | I38: =G38-C38 -> 0 | L38: =+E38-F38 -> 0
A39: 1362100 | B39: ເງິນຈ່າຍລ່ວງໜ້າເພື່ອເຄື່ອນໄຫວວຽກງານ | C39: 36400000 | D39: 0 | E39: 243979076 | F39: 279879076 | G39: 500000 | H39: 0 | I39: =G39-C39 -> -35900000 | L39: =+E39-F39 -> -35900000
A40: 1388110 | B40: ຄ່າເຊົ່າຈ່າຍລ່ວງໜ້າ | C40: 23950902 | D40: 0 | E40: 9.7255238e+08 | F40: 5.5573423e+08 | G40: 4.4076906e+08 | H40: 0 | I40: =G40-C40 -> 4.1681815e+08 | L40: =+E40-F40 -> 4.1681815e+08
...

Sheet BS
A1: ສາທາລະນະລັດ ປະຊາທິປະໄຕ ປະຊາຊົນລາວ | B1: ສັນຕິພາບ ເອກະລາດ ປະຊາທິປະໄຕ ເອກະພາບ ວັດທະນາຖາວອນ
A2: ບໍລິສັດຫຼັກຊັບ ທຄຕລ-ກທ ຈຳກັດ_x000D_ ຊັ້ນ7, ຕຶກຕະຫຼາກຫຼັກຊັບລາວ, ຖະໜົນກຳແພງເມືອງ_x000D_ +856-21-265477+856-21-265488
D3: ໃບສະຫລຸບຊັບສົມບັດ | E3: ໃນປີ 2012
A4: ລ/ດ | B4: ເລກບັນຊີ | C4: ເນື້ອໃນລາຍການ | D4: ປີນີ້ | E4: ປີກ່ອນ
A5: 1 | B5: 1. ​ເງິນສົດ ​ແລະ ທຽບ​ເທົ່​າເງິນສົດ | D5: 4468000 | E5: 10000000
A6: 1 | B6: 1101100 | C6: ເງິນສົດໃນຄັງ " HO " ກີບ | D6: 4468000 | E6: 10000000
A7: 2 | B7: 2.1. ເງິນຝາກທະນາຄານ | D7: 1.5681483e+11 | E7: 1.3662937e+11
A8: 2 | B8: 1131115 | C8: ບັນຊີກະແສລາຍວັນ ທຄຕລ Aggregate AC: 010.4.19.00.00010 ( ກີບ ) | D8: 55650947823 | E8: 39741098167
A9: 3 | B9: 1131116 | C9: ບັນຊີກະແສລາຍວັນ ທຄຕລ for ETL staff IPO AC: 010.9.00.00001 ( ກີບ ) | D9: 100000 | E9: 100000
A10: 4 | B10: 1131154 | C10: ບັນຊີຝາກມີກຳນົດທີ່ ທສກ: 0402.0402.00.2131315.47.00000004 ( ກີບ ) | D10: 25000000000 | E10: 0
B11: 1131110 | C11: ບັນຊີກະແສລາຍວັນ ທຄຕລ: 010.0.11.00.24740 ( ກີບ ) | D11: 137607.24 | E11: 652607.74
A12: 6 | B12: 1131159 | C12: ບັນຊີຝາກມີກຳນົດທີ່ ST Bank: 010.5.35.00.08899 ( ກີບ ) | D12: 5000000000 | E12: 0
A13: 7 | B13: 1131113 | C13: ບັນຊີກະແສລາຍວັນ ທຄຕລ Proprietary AC: 010.4.19.00.00009 ( ກີບ ) | D13: 294629790 | E13: 92595445
A14: 8 | B14: 1131162 | C14: ບັນຊີເງິນຝາກມີກຳນົດ ທີ່ ທະນາຄານ ເອຊີລີດາ ( ກີບ ) | D14: 35000000000 | E14: 0
A15: 9 | B15: 1131111 | C15: ບັນຊີກະແສລາຍວັນ ທຄຕລ: 010.7.11.02.08233 ( ບາດ ) | D15: 1788525.4 | E15: 713249.55
A16: 10 | B16: 1131134 | C16: ບັນຊີຝາກປະຢັດທີ່ ທສກ: 0402.0.00.220130 ( ກີບ ) | D16: 3469166998 | E16: 1358879432
A17: 11 | B17: 1131131 | C17: ບັນຊີຝາກປະຢັດທີ່ ທຄຕລ: 013.9.12.01.00001 ( ໂດລ່າ ) | D17: 30012667 | E17: 8.9027339e+08
A18: 12 | B18: 1121110 | C18: ບັນຊີທຶນຈົດທະບຽນຂອງ ທຄຕລ-ກທ ຈຳກັດ ( ກີບ ) | D18: 2.2816035e+09 | E18: 7.2281614e+10
A19: 13 | B19: 1131112 | C19: ບັນຊີກະແສລາຍວັນ ທຄຕລ: 010.9.11.01.19243 ( ໂດລ່າ ) | D19: 1594317.1 | E19: 1641620.4
A20: 14 | B20: 1131121 | C20: ບັນຊີກະແສລາຍວັນ ເອຊີລີດາ 123359-1-1-101 | D20: 1000000 | E20: 0
A21: 15 | B21: 1131153 | C21: ບັນຊີຝາກມີກຳນົດທີ່ ທສກ: 0402.0402.00.2131315.47.00000003 ( ກີບ ) | D21: 20000000000 | E21: 20000000000
A22: 16 | B22: 1131130 | C22: ບັນຊີຝາກປະຢັດທີ່ ທຄຕລ: 013.2.12.00.00036 ກີບ | D22: 9.2493495e+09 | E22: 2.2618014e+09
A23: 17 | B23: 1131137 | C23: ບັນຊີຝາກປະຍັດ ທຄຕລ-ກທ ທີ່ ເອຊີລີດາ 123359-1-0-0101 ( ກີບ ) | D23: 8.3449851e+08 | E23: 0
A24: 3 | B24: 3.1. ເງິນລົງທຶນໄລຍະສັ້ນ | D24: 5.149202e+08 | E24: 79930000
A25: 18 | B25: 1302216 | C25: ເງິນລົງທືນຊົ່ວຄາວຫຼັກຊັບ-ເພື່ອຄ້າ-Port Trading | D25: 4.7421994e+08 | E25: 117180970
A26: 19 | B26: 1302218 | C26: ຄ່າປັບມູນຄ່າເງິນລົງທືນຊົ່ວຄາວຫຼັກຊັບ-ເພື່ອຄ້າ-Port trading | D26: 40700260 | E26: -37250970
A27: 4 | B27: 4.1. ໜີ້ຕ້ອງ​ຮັບ​ທາງການຄ້າ | D27: 58820889 | E27: 4284683
A28: 20 | B28: 1201181 | C28: ລູກໜີ້ຊື້ຫຼັກຊັບຕາມຄຳສັ່ງຊື້-ບັນຊີເງິນສົດ | D28: 58820889 | E28: 4284683
A29: 5 | B29: 4.3. ໜີ້ຕ້ອງ​ຮັບ​ລະຫວ່າງ​ບໍລິສັດໃນກຸ່ມ | C29: 0 | D29: 23823233
A30: 21 | B30: 1211110 | C30: ລູກໜີ້ບັນຊີຊື້-ຂາຍຫຼັກຊັບລະຫວ່າງບ/ສ ກັບ LSX | D30: 0 | E30: 23823233
A31: 6 | B31: 6. ຊັບສິນໝູນວຽນອື່ນໆ | D31: 6468583 | E31: 1.526439e+08
A32: 22 | B32: 1360000 | C32: ລູກໜີ້ອື່ນໆ | D32: 5968583 | E32: 61100181
A33: 23 | B33: 1361300 | C33: ອາກອນອື່ນໆທີ່ຕ້ອງຮັບຄືນ | D33: -7.4505806e-09 | E33: 27382364
A34: 24 | B34: 1362100 | C34: ເງິນຈ່າຍລ່ວງໜ້າເພື່ອເຄື່ອນໄຫວວຽກງານ | D34: 500000 | E34: 36400000
A35: 25 | B35: 1361100 | C35: ອາກອນກຳໄລມອບລ່ວງໜ້າ | D35: 0 | E35: 27761356
A36: 7 | B36: 2. ຊັບສິນຄົງທີ່ບໍ່ມີຕົວຕົນ | D36: 3.0777805e+08 | E36: 2.7021397e+08
A37: 26 | B37: 1441810 | C37: ຊັອບແວຄອມພີວເຕີ່ | D37: 3.0777805e+08 | E37: 2.7021397e+08
A38: 8 | B38: 3. ຊັບ​ສົມບັດຄົງ​ທີ່​ມີຕົວຕົນ | D38: 3.3460869e+09 | E38: 3.1995897e+09
A39: 27 | B39: 1442510 | C39: ຄ່າຕົບແຕ່ງສຳນັກງານ | D39: 1.5476721e+09 | E39: 1.5394821e+09
A40: 28 | B40: 1442400 | C40: ພາຫະນະຂົນສົ່ງ | D40: 629368000 | E40: 615368000
...

Sheet PL
A1: ສາທາລະນະລັດ ປະຊາທິປະໄຕ ປະຊາຊົນລາວ | B1: ສັນຕິພາບ ເອກະລາດ ປະຊາທິປະໄຕ ເອກະພາບ ວັດທະນາຖາວອນ
A2: ບໍລິສັດຫຼັກຊັບ ທຄຕລ-ກທ ຈຳກັດ_x000D_ ຊັ້ນ7, ຕຶກຕະຫຼາກຫຼັກຊັບລາວ, ຖະໜົນກຳແພງເມືອງ_x000D_ +856-21-265477+856-21-265488
D3: ໃບລາຍງານຜົນໄດ້ຮັບ | E3: ໃນປີ 2012
A4: ເອກະສານຊ້ອນທ້າຍ
A5: ລຳດັບ | B5: ລາຍຮັບ | C5: 1.1 | D5: 0 | E5: 0
A6: I | B6: ລາຍຮັບຈາກການດຳເນີນງານ | C6: 1.1.1 | D6: 5.4220711e+10 | E6: 0
B7: 1. ຄ່ານາຍໜ້າຈາກການຊື້-ຂາຍຫຼັກຊັບ | C7: 1.1.1.1 | D7: 1698263965 | E7: 0
B8: 2. ຄ່າບໍລິການ | C8: 1.1.1.2 | D8: 4.7128415e+10 | E8: 0
B9: 2.1. ຄ່າບໍລິການໃຫ້ຄຳປຶກສາທາງດ້ານການເງິນ | C9: 1.1.1.2.1 | D9: 4.3376696e+09 | E9: 0
B10: 2.2. ຄ່າບໍລິການ ຄໍ້າປະກັນການຈັດຈຳໜ່າຍຫຼັກຊັບ | C10: 1.1.1.2.2 | D10: 42790745204 | E10: 0
B11: 2.3. ຄ່າບໍລິການ ເປັນຕົວແທນຈຳໝ່າຍຫຼັກຊັບ | C11: 1.1.1.2.3 | D11: 0 | E11: 0
B12: 3. ກຳໄລ(ຂາດທຶນ)ຈາກການຊື້ຂາຍຫຼັກຊັບ | C12: 1.1.1.3 | D12: 74367920 | E12: 0
B13: 4. ດອກເບ້ຍ ແລະ ເງິນປັນຜົນ | C13: 1.1.1.4 | D13: 5.3196641e+09 | E13: 0
A14: II | B14: ລາຍຮັບອື່ນໆ | C14: 1.1.2 | D14: -1.4064442e+08 | E14: 0
B15: ລາຍຮັບອື່ນໆ | C15: 1.1.2.5 | D15: -1.4064442e+08 | E15: 0
B16: ລວມຍອດລາຍຮັບ | C16: 1.13 | D16: 5.4080066e+10 | E16: 0
A17: ລຳດັບ | B17: ລາຍຈ່າຍ | C17: 1.2. | D17: 0 | E17: 0
A18: I | B18: ລາຍຈ່າຍຈາກການດຳເນີນງານ | C18: 1.2.1 | D18: 4.2748984e+10 | E18: 0
B19: 1. ລາຍຈ່າຍຄ່ານາຍໜ້າຊື້-ຂາຍຫຼັກຊັບ | C19: 1.2.1.1.1 | D19: 1.0378224e+09 | E19: 0
B20: 2. ລາຍຈ່າຍຄ່າໃຫ້ຄຳປຶກສາທາງການເງິນ | C20: 1.2.1.1.2 | D20: 4.1056803e+10 | E20: 0
B21: 3. ລາຍຈ່າຍຄ່າໃຫ້ການຄໍ້າປະກັນການຈັດຈຳໜ່າຍຫຼັກຊັບ | C21: 1.2.1.1.3 | D21: 0 | E21: 0
B22: 4. ລາຍຈ່າຍການຄ້າຫຼັກຊັບ | C22: 1.2.1.1.4 | D22: 0 | E22: 0
B23: 5. ລາຍຈ່າຍອື່ນໆທາງດ້ານຫຼັກຊັບ | C23: 1.2.1.1.5 | D23: 6.5435877e+08 | E23: 0
A24: II | B24: ລາຍຈ່າຍໃນການບໍລິຫານ | C24: 1.2.2 | D24: 6.0327915e+09 | E24: 0
B25: 1. ລາຍຈ່າຍກ່ຽວກັບພະນັກງານ | C25: 1.2.2.2.1 | D25: 3.3459934e+09 | E25: 0
B26: 2. ຄ່າຫລຸ້ຍຫ້ຽນອາຄານສະຖານທີ່ ແລະ ອຸປະກອນ | C26: 1.2.2.2.2 | D26: 4.3048138e+08 | E26: 0
B27: 3. ລາຍຈ່າຍພາສີອາກອນ | C27: 1.2.2.2.3 | D27: 77870728 | E27: 0
B28: 4. ລາຍຈ່າຍອື່ນໆ | C28: 1.2.2.2.4 | D28: 2.178446e+09 | E28: 0
A29: III | B29: ລາຍຈ່າຍດອກເບ້ຍເງິນກູ້ຢືມ | C29: 1.2.3 | D29: 0 | E29: 0
B30: ລາຍຈ່າຍດອກເບ້ຍເງິນກູ້ຢືມ | C30: 1.2.3.3.1 | D30: 0 | E30: 0
B31: ລວມຍອດລາຍຈ່າຍ | C31: 1.2.4 | D31: 4.8781776e+10 | E31: 0
B32: ກຳໄລກ່ອນອາກອນ | C32: 1.2.4.1 | D32: 5.2982905e+09 | E32: 0
B33: ອາກອນກຳໄລ | C33: 1.2.4.2 | D33: 1.534075e+09 | E33: 0
B34: ກຳໄລສຸດທິ | C34: 1.2.4.3 | D34: 3.7642156e+09 | E34: 0
A35: ນະຄອນຫຼວງວຽງຈັນ ວັນທີ : ......../......../............ , | B35: ຜູ້ອຳນວຍການ | C35: ທີ່ປຶກສາບັນຊີ | D35: ພະນັກງານບັນຊີ | E35: ຜູ້ສັງລວມ | F35: ............…………………...... | G35: ............…………………...... | H35: ............…………………...... | I35: ............…………………...... | J35: ...………………………….. | K35: ...………………………….. | L35: ...………………………….. | M35: ...…………………………..
A36: 1
