Workbook

Sheet Sheet1
A1: ໂລໂກ້ | G1: Logo Company
A2: ບໍລິສັດ………….. | G2: BCEL-KT Securities Co.,Ltd
A3: ເບີໂທ..……………. | G3: Tel: , Fax:
B4: ໃບລາຍງານກະແສເງິນສົດ | H4: Cash flow statment
B5: ປະຈຳປີ............... | H5: Yearly:...............
B6: ຫົວໜ່ວຍ: 1.000.000ກີບ | H6: Unit: 1.000.000 Lak
A7: ລຳດັບ | B7: ລາຍການ | C7: ເອກະສານຊ້ອນທ້າຍ | D7: ຈຳນວນເງິນ | G7: No | H7: Descriptions | I7: Note | J7: Amount
D8: ປີນີ້ | E8: ປີກ່ອນ | J8: This Year | K8: Last Year
A9: I | B9: ກະແສເງິນສົດຈາກກິດຈະກຳການດຳເນີນງານ | G9: I | H9: Cash flows from operating activities
B10: 1. ​ກໍາໄລ ຫຼື ຂາດທຶນສຸດທິກ່ອນອາກອນ | D10: 0 | E10: 0 | H10: 1. ​Net profit before tax for the period | J10: 0 | K10: 0
B11: 2. ລາຍການປັບປຸງຍອດກຳໄລ ຫຼື ຍອດຂາດທຶນເປັນເງິນສົດຮັບ-ຈ່າຍ | D11: =+D12+D13+D14+D15+D16+D17 -> 0 | E11: =+E12+E13+E14+E15+E16+E17 -> 0 | H11: 2. Adjustments to reconcile net profit to | J11: =+J12+J13+J14+J15+J16+J17 -> 0 | K11: =+K12+K13+K14+K15+K16+K17 -> 0
B12: 2.1. ຄ່າຫຼຸ້ຍຫ້ຽນ ແລະ ຄ່າເສື່ອມມູນຄ່າສຸດທິຂອງຊັບສົມບັດຄົງທີ່ມີຕົວຕົນ ແລະ ບໍ່ມີຕົວຕົນ | D12: 0 | E12: 0 | H12: 2.1. Depreciation | J12: 0 | K12: 0
B13: 2.2. ຄ່າເສື່ອມມູນຄ່າສຸດທິຂອງເງິນລົງທຶນໃນຫຼັກຊັບ ແລະ ລາຍການອື່ນໆ | D13: 0 | E13: 0 | H13: 2.2. Amortization | J13: 0 | K13: 0
B14: 2.3. ຂາດທຶນຈາກການຂາຍຊັບສົມບັດຄົງທີ່ | D14: 0 | E14: 0 | H14: 2.3. Loss on Disposal | J14: 0 | K14: 0
B15: 2.4. ກຳໄລຈາກການຂາຍຊັບສົມບັດຄົງທີ່ | D15: 0 | E15: 0 | H15: 2.4. Gain on Disposal | J15: 0 | K15: 0
B16: 2.5. ສ່ວນປ່ຽນແປງໃນລາຍການດອກເບ້ຍ ແລະ ລາຍຮັບອື່ນໆຄ້າງຮັບ | D16: 0 | E16: 0 | H16: 2.5. Unrealized (gain) loss on investment | J16: 0 | K16: 0
B17: 2.6. ສ່ວນປ່ຽນແປງໃນລາຍການດອກເບ້ຍ ແລະ ລາຍຈ່າຍອື່ນໆຄ້າງຈ່າຍ | D17: 0 | E17: 0 | H17: 2.6. Unrealized gain(loss) on exchange rate | J17: 0 | K17: 0
B18: ກ. ກະແສເງິນສົດສຸດທິຈາກກິດຈະກຳການດຳເນີນງານກ່ອນການປ່ຽນແປງໃນລາຍການຊັບສິນ ແລະ ໜີ້ສິນໝູນວຽນ | D18: =+D10+D11 -> 0 | E18: =+E10+E11 -> 0 | H18: A. Net loss from operating activities before changes in operating assets and liabilities | J18: =+J10+J11 -> 0 | K18: =+K10+K11 -> 0
B19: 3. ການປ່ຽນແປງ(ເພີ່ມຂຶ້ນ ຫຼື ຫຼຸດລົງ) ໃນລາຍການຊັບສິນໝູນວຽນ | D19: =+D20+D21+D22+D23+D24+D25+D26+D27 -> 0 | E19: =+E20+E21+E22+E23+E24+E25+E26+E27 -> 0 | H19: 3. Increase/Decrease in operating assets:- | J19: =+J20+J21+J22+J23+J24+J25+J26+J27 -> 0 | K19: =+K20+K21+K22+K23+K24+K25+K26+K27 -> 0
B20: 3.1. ເງິນຝາກທະນາຄານ ແລະ ສະຖາບັນການເງິນ | D20: 0 | E20: 0 | H20: 3.1. Deposit with banks and financial institutions | J20: 0 | K20: 0
B21: 3.2. ເງິນລົງທຶນໄລຍະສັ້ນ | D21: 0 | E21: 0 | H21: 3.2. Shorterm Investement "Investment in securities" | J21: 0 | K21: 0
B22: 3.3. ໜີ້ຕ້ອງຮັບທາງການຄ້າ | D22: 0 | E22: 0 | H22: 3.3. A/R on business | J22: 0 | K22: 0
B23: 3.4. ໜີ້ຕ້ອງຮັບທາງທຸລະກຳຫຼັກຊັບ | D23: 0 | E23: 0 | H23: 3.4. A/R Securities on Business | J23: 0 | K23: 0
B24: 3.5. ໜີ້ຕ້ອງຮັບລະຫວ່າງບໍລິສັດໃນກຸ່ມ | D24: 0 | E24: 0 | H24: 3.5. A/R clearing house | J24: 0 | K24: 0
B25: 3.6. ໜີ້ຕ້ອງຮັບອື່ນໆ | D25: 0 | E25: 0 | H25: 3.6. Other account receivable | J25: 0 | K25: 0
B26: 3.7. ເຄື່ອງໃນສາງ | D26: 0 | E26: 0 | H26: 3.7. Inventory | J26: 0 | K26: 0
B27: 3.8. ຊັບສິນໝູນວຽນອື່ນໆ | D27: 0 | E27: 0 | H27: 3.8. Other current assets | J27: 0 | K27: 0
B28: ຂ. ກະແສເງິນສົດສຸດທິຈາກການປ່ຽນແປງໃນຊັບສິນໝູນວຽນ | D28: =+D19 -> 0 | E28: =+E19 -> 0 | H28: B. Net Cash flow statement in operating assets | J28: =+J19 -> 0 | K28: =+K19 -> 0
B29: 4. ການປ່ຽນແປງ(ເພີ່ມຂຶ້ນ ຫຼື ຫຼຸດລົງ) ໃນລາຍການໜີ້ສິນໝູນວຽນ | D29: =+D30+D31+D32+D33+D34+D35 -> 0 | E29: =+E30+E31+E32+E33+E34+E35 -> 0 | H29: 4. Increase/Decrease in operating liabilities:- | J29: =+J30+J31+J32+J33+J34+J35 -> 0 | K29: =+K30+K31+K32+K33+K34+K35 -> 0
B30: 4.1. ໜີ້ຕ້ອງສົ່ງທາງການຄ້າ | D30: 0 | E30: 0 | H30: 4.1. A/P on business | J30: 0 | K30: 0
B31: 4.2. ໜີ້ຕ້ອງສົ່ງທາງທຸລະກຳຫຼັກຊັບ | D31: 0 | E31: 0 | H31: 4.2. A/P Securities on Business | J31: 0 | K31: 0
B32: 4.3. ໜີ້ຕ້ອງສົ່ງລະຫວ່າງບໍລິສັດໃນກຸ່ມ | D32: 0 | E32: 0 | H32: 4.3. A/R clearing house | J32: 0 | K32: 0
B33: 4.4. ອາກອນກຳໄລຄ້າງຈ່າຍ | D33: 0 | E33: 0 | H33: 4.4. Accrued corporate income tax | J33: 0 | K33: 0
B34: 4.5. ໜີ້ຕ້ອງສົ່ງອື່ນໆ | D34: 0 | E34: 0 | H34: 4.5. Other liabilities | J34: 0 | K34: 0
B35: 4.6. ໜີ້ສິນໝູນວຽນອື່ນໆ | D35: 0 | E35: 0 | H35: 4.6. Subscription payable | J35: 0 | K35: 0
B36: ຄ. ກະແສເງິນສົດສຸດທິຈາກການປ່ຽນແປງໃນໜີ້ສິນໝູນວຽນ | D36: =+D29 -> 0 | E36: =+E29 -> 0 | H36: C. Net Cash flow statement in operating Liabilities | J36: =+J29 -> 0 | K36: =+K29 -> 0
B37: ກະແສເງິນສົດສຸດທິຈາກກິດຈະກຳດຳເນີນງານ | D37: =+D18+D28+D36 -> 0 | E37: =+E18+E28+E36 -> 0 | H37: Net Cash flows from operating activities | J37: =+J18+J28+J36 -> 0 | K37: =+K18+K28+K36 -> 0
A38: II | B38: ​ກະແສເງິນສົດຈາກກິດຈະກໍາລົງທຶນ | G38: II | H38: Cash flows from investing activities
B39: 1. ສ່ວນເພີ່ມຫຼືຫຼຸດໃນລາຍການເງິນລົງທຶນໄລຍະຍາວ | D39: 0 | E39: 0 | H39: 1. Increase/Decrease on long term investment | J39: 0 | K39: 0
B40: 2. ສ່ວນເພີ່ມຫຼືຫຼຸດໃນລາຍໜີ້ຕ້ອງຮັບໄລຍະຍາວ ແລະ ຊັບສິນໄລຍະຍາວອື່ນໆ | D40: 0 | E40: 0 | H40: 2. Increase/Decrease A/R and other assets on long term investment | J40: 0 | K40: 0
...

Sheet Sheet2
A1: ໂລໂກ້
A2: ບໍລິສັດ…………..
A3: ເບີໂທ..…………….
B4: ໃບລາຍງານກະແສເງິນສົດ
B5: ປະຈຳປີ...............
B6: ຫົວໜ່ວຍ: 1.000.000ກີບ
A7: ລຳດັບ | B7: ລາຍການ
B8: ລາຍການ | C8: ເຄື່ອງໝາຍ | D8: ເລກບັນຊີ
A9: I | B9: ກະແສເງິນສົດຈາກກິດຈະກຳການດຳເນີນງານ
B10: 1. ​ກໍາໄລ ຫຼື ຂາດທຶນສຸດທິກ່ອນອາກອນ | D10: ຍອດເຫຼືອບັນຊີ 3901
B11: 2. ລາຍການປັບປຸງຍອດກຳໄລ ຫຼື ຍອດຂາດທຶນເປັນເງິນສົດຮັບ-ຈ່າຍ
B12: 2.1. ຄ່າຫຼຸ້ຍຫ້ຽນ ແລະ ຄ່າເສື່ອມມູນຄ່າສຸດທິຂອງຊັບສົມບັດຄົງທີ່ມີຕົວຕົນ ແລະ ບໍ່ມີຕົວຕົນ | C12: +/- | D12: ບ/ຊ 148
B13: 2.2. ຄ່າເສື່ອມມູນຄ່າສຸດທິຂອງເງິນລົງທຶນໃນຫຼັກຊັບ ແລະ ລາຍການອື່ນໆ | C13: +/- | D13: ບ/ຊ 1319+1419+1199111+1199121+1199131+1199141+1199211+1199231+1199241+
D14: 1299111+1299121+1299131+1299141+1299211+1299221+1299231+1199241+1199112+
D15: 1199113+1199122+1199123+1199132+1199133+1199142+1199143+1199212+1199213+
D16: 1199222+1199223+1199232+1199233+1199242+1199243+1299112+1299113+1299122+
D17: 1299123+1299132+1299133+1299142+1299143+1299212+1299222+1299232+1299142
B18: 2.3. ຂາດທຶນຈາກການຂາຍຊັບສົມບັດຄົງທີ່ | C18: + | D18: ບ/ຊ 4506+410416
B19: 2.4. ກຳໄລຈາກການຂາຍຊັບສົມບັດຄົງທີ່ | C19: - | D19: ບ/ຊ 5506+510416+510426
B20: 2.5. ສ່ວນປ່ຽນແປງໃນລາຍການດອກເບ້ຍ ແລະ ລາຍຮັບອື່ນໆຄ້າງຮັບ | D20: What account No ??????? | E20: None
B21: 2.6. ສ່ວນປ່ຽນແປງໃນລາຍການດອກເບ້ຍ ແລະ ລາຍຈ່າຍອື່ນໆຄ້າງຈ່າຍ | D21: What account No ??????? | E21: None
B22: ກ. ກະແສເງິນສົດສຸດທິຈາກກິດຈະກຳການດຳເນີນງານກ່ອນການປ່ຽນແປງໃນລາຍການຊັບສິນ ແລະ ໜີ້ສິນໝູນວຽນ | D22: ກ=3(Item 3.1 to Item 3.8)
B24: 3. ການປ່ຽນແປງ(ເພີ່ມຂຶ້ນ ຫຼື ຫຼຸດລົງ) ໃນລາຍການຊັບສິນໝູນວຽນ
B25: 3.1. ເງິນຝາກທະນາຄານ ແລະ ສະຖາບັນການເງິນ | C25: -/+ | D25: ບ/ຊ 1121+1131+1122
B26: 3.2. ເງິນລົງທຶນໄລຍະສັ້ນ | C26: -/+ | D26: ບ/ຊ 13011+13021+13025+13026+(130311-130391)+(130312-130392)+130351+130352+1311
B27: 3.3. ໜີ້ຕ້ອງຮັບທາງການຄ້າ | C27: -/+ | D27: ບ/ຊ 12011
B28: 3.4. ໜີ້ຕ້ອງຮັບທາງທຸລະກຳຫຼັກຊັບ | C28: -/+ | D28: ບ/ຊ 120611+12311+123151+1241+1261
B29: 3.5. ໜີ້ຕ້ອງຮັບລະຫວ່າງບໍລິສັດໃນກຸ່ມ | C29: -/+ | D29: ບ/ຊ 12111+121121
B30: 3.6. ໜີ້ຕ້ອງຮັບອື່ນໆ | C30: -/+ | D30: ບ/ຊ 113211+1132121+113221+1132221+119111+119121+119131+119141+119211+
D31: 119221+119231+119241+1207+129111+12921+129131+129141+129211+129221+129231+
D32: 129241
B33: 3.7. ເຄື່ອງໃນສາງ | C33: -/+ | D33: ບ/ຊ 1371+1373+1376+1378-1379
B34: 3.8. ຊັບສິນໝູນວຽນອື່ນໆ | C34: -/+ | D34: ບ/ຊ 1361+1362+138+1138
B35: ຂ. ກະແສເງິນສົດສຸດທິຈາກການປ່ຽນແປງໃນຊັບສິນໝູນວຽນ
B36: 4. ການປ່ຽນແປງ(ເພີ່ມຂຶ້ນ ຫຼື ຫຼຸດລົງ) ໃນລາຍການໜີ້ສິນໝູນວຽນ
B37: 4.1. ໜີ້ຕ້ອງສົ່ງທາງການຄ້າ | C37: +/- | D37: ບ/ຊ 2127+2137+21472167+2237+2247+2267+23017+23027+23317+23327+23357+23367+
D38: 2347+2367
B39: 4.2. ໜີ້ຕ້ອງສົ່ງທາງທຸລະກຳຫຼັກຊັບ | C39: +/- | D39: ບ/ຊ 23011+23021+23022+231+23311+23321+23351+2341+2342+2343+2344+2346
B40: 4.3. ໜີ້ຕ້ອງສົ່ງລະຫວ່າງບໍລິສັດໃນກຸ່ມ | C40: + | D40: ບ/ຊ 22111+22121
B41: 4.4. ອາກອນກຳໄລຄ້າງຈ່າຍ | C41: +/- | D41: ບ/ຊ 236111
...

Sheet FinalFormwFx2
A1: ໂລໂກ້
A2: ບໍລິສັດ…………..
A3: ເບີໂທ..…………….
B4: ໃບລາຍງານກະແສເງິນສົດ
B5: ປະຈຳປີ...............
B6: ຫົວໜ່ວຍ: 1.000.000ກີບ
A7: ລຳດັບ | B7: ລາຍການ
B8: ລາຍການ | C8: ເຄື່ອງໝາຍ | D8: ເລກບັນຊີ
A9: I | B9: ກະແສເງິນສົດຈາກກິດຈະກຳການດຳເນີນງານ
B10: 1. ​ກໍາໄລ ຫຼື ຂາດທຶນສຸດທິກ່ອນອາກອນ | D10: ຍອດເຫຼືອບັນຊີ 3901
B11: 2. ລາຍການປັບປຸງຍອດກຳໄລ ຫຼື ຍອດຂາດທຶນເປັນເງິນສົດຮັບ-ຈ່າຍ
B12: 2.1. ຄ່າຫຼຸ້ຍຫ້ຽນ ແລະ ຄ່າເສື່ອມມູນຄ່າສຸດທິຂອງຊັບສົມບັດຄົງທີ່ມີຕົວຕົນ ແລະ ບໍ່ມີຕົວຕົນ | C12: +/- | D12: ບ/ຊ 148
B13: 2.2. ຄ່າເສື່ອມມູນຄ່າສຸດທິຂອງເງິນລົງທຶນໃນຫຼັກຊັບ ແລະ ລາຍການອື່ນໆ | C13: +/- | D13: ບ/ຊ 1319+1419+1199111+1199121+1199131+1199141+1199211+1199231+1199241+
D14: 1299111+1299121+1299131+1299141+1299211+1299221+1299231+1199241+1199112+
D15: 1199113+1199122+1199123+1199132+1199133+1199142+1199143+1199212+1199213+
D16: 1199222+1199223+1199232+1199233+1199242+1199243+1299112+1299113+1299122+
D17: 1299123+1299132+1299133+1299142+1299143+1299212+1299222+1299232+1299142
B18: 2.3. ຂາດທຶນຈາກການຂາຍຊັບສົມບັດຄົງທີ່ | C18: + | D18: ບ/ຊ 4506+410416
B19: 2.4. ກຳໄລຈາກການຂາຍຊັບສົມບັດຄົງທີ່ | C19: - | D19: ບ/ຊ 5506+510416+510426
B20: 2.5. ສ່ວນປ່ຽນແປງໃນລາຍການດອກເບ້ຍ ແລະ ລາຍຮັບອື່ນໆຄ້າງຮັບ
B21: 2.6. ສ່ວນປ່ຽນແປງໃນລາຍການດອກເບ້ຍ ແລະ ລາຍຈ່າຍອື່ນໆຄ້າງຈ່າຍ
B22: ກ. ກະແສເງິນສົດສຸດທິຈາກກິດຈະກຳການດຳເນີນງານກ່ອນການປ່ຽນແປງໃນລາຍການຊັບສິນ ແລະ ໜີ້ສິນໝູນວຽນ
B24: 3. ການປ່ຽນແປງ(ເພີ່ມຂຶ້ນ ຫຼື ຫຼຸດລົງ) ໃນລາຍການຊັບສິນໝູນວຽນ
B25: 3.1. ເງິນຝາກທະນາຄານ ແລະ ສະຖາບັນການເງິນ | C25: -/+ | D25: ບ/ຊ 1121+1131+1122
B26: 3.2. ເງິນລົງທຶນໄລຍະສັ້ນ | C26: -/+ | D26: ບ/ຊ 13011+13021+13025+13026+(130311-130391)+(130312-130392)+130351+130352+1311
B27: 3.3. ໜີ້ຕ້ອງຮັບທາງການຄ້າ | C27: -/+ | D27: ບ/ຊ 12011
B28: 3.4. ໜີ້ຕ້ອງຮັບທາງທຸລະກຳຫຼັກຊັບ | C28: -/+ | D28: ບ/ຊ 120611+12311+123151+1241+1261
B29: 3.5. ໜີ້ຕ້ອງຮັບລະຫວ່າງບໍລິສັດໃນກຸ່ມ | C29: -/+ | D29: ບ/ຊ 12111+121121
B30: 3.6. ໜີ້ຕ້ອງຮັບອື່ນໆ | C30: -/+ | D30: ບ/ຊ 113211+1132121+113221+1132221+119111+119121+119131+119141+119211+
D31: 119221+119231+119241+1207+129111+12921+129131+129141+129211+129221+129231+
D32: 129241
B33: 3.7. ເຄື່ອງໃນສາງ | C33: -/+ | D33: ບ/ຊ 1371+1373+1376+1378-1379
B34: 3.8. ຊັບສິນໝູນວຽນອື່ນໆ | C34: -/+ | D34: ບ/ຊ 1361+1362+138+1138+1360000 | E34: ????????????
B35: ຂ. ກະແສເງິນສົດສຸດທິຈາກການປ່ຽນແປງໃນຊັບສິນໝູນວຽນ
B36: 4. ການປ່ຽນແປງ(ເພີ່ມຂຶ້ນ ຫຼື ຫຼຸດລົງ) ໃນລາຍການໜີ້ສິນໝູນວຽນ
B37: 4.1. ໜີ້ຕ້ອງສົ່ງທາງການຄ້າ | C37: +/- | D37: ບ/ຊ 2127+2137+21472167+2237+2247+2267+23017+23027+23317+23327+23357+23367+
D38: 2347+2367
B39: 4.2. ໜີ້ຕ້ອງສົ່ງທາງທຸລະກຳຫຼັກຊັບ | C39: +/- | D39: ບ/ຊ 23011+23021+23022+231+23311+23321+23351+2341+2342+2343+2344+2346
B40: 4.3. ໜີ້ຕ້ອງສົ່ງລະຫວ່າງບໍລິສັດໃນກຸ່ມ | C40: + | D40: ບ/ຊ 22111+22121
B41: 4.4. ອາກອນກຳໄລຄ້າງຈ່າຍ | C41: +/- | D41: ບ/ຊ 236111
...

Sheet Cash flow statement 
A1: ໂລໂກ້
A2: ບໍລິສັດ…………..
A3: ເບີໂທ..…………….
B4: ໃບລາຍງານກະແສເງິນສົດ
B5: ປະຈຳປີ: 2012 | K5: Note for A/C
B6: ຫົວໜ່ວຍ: 1.000.000ກີບ
A7: ລຳດັບ | B7: ລາຍການ | C7: ເອກະສານຊ້ອນທ້າຍ | D7: ຈຳນວນເງິນ
D8: ປີນີ້ | E8: Jan'13 | F8: Feb'13 | G8: Mar'13 | H8: June'13 | I8: Dec'13
A9: I | B9: ກະແສເງິນສົດຈາກກິດຈະກຳການດຳເນີນງານ
B10: 1. ​ກໍາໄລ ຫຼື ຂາດທຶນສຸດທິກ່ອນອາກອນ | D10: =SUM('TB 2012'!J86:J172)/1000 -> 3764215.6 | E10: =+SUM('TB JAn''13'!I80:I136) -> 2.4392347e+08 | F10: =+SUM('TB Feb''13'!I80:I139) -> 3.8434523e+08 | G10: =+SUM('TB March''13'!I81:I149) -> 869899.41 | H10: =+SUM('TB June''13'!I83:I159) -> 1.611895e+08 | I10: =+SUM('TB for 2013'!F89) -> 3.2704856e+09 | K10: Cr-Dr " Movement of 4-5 "+ A/C: 39
B11: 2. ລາຍການປັບປຸງຍອດກຳໄລ ຫຼື ຍອດຂາດທຶນເປັນເງິນສົດຮັບ-ຈ່າຍ | D11: =+D12+D13+D14+D15+D16+D17 -> 418699.01 | E11: =+E12+E13+E14+E15+E16+E17 -> 39596229 | F11: =+F12+F13+F14+F15+F16+F17 -> 28187123 | G11: =+G12+G13+G14+G15+G16+G17 -> 37983112 | H11: =+H12+H13+H14+H15+H16+H17 -> 37654393 | I11: =+I12+I13+I14+I15+I16+I17 -> 4.5097972e+08
B12: 2.1. ຄ່າຫຼຸ້ຍຫ້ຽນ ແລະ ຄ່າເສື່ອມມູນຄ່າສຸດທິຂອງຊັບສົມບັດຄົງທີ່ມີຕົວຕົນ ແລະ ບໍ່ມີຕົວຕົນ | D12: =SUM('TB 2012'!J50:J56)/1000 -> 418699.01 | E12: =+SUM('TB JAn''13'!J47:J52) -> 39596229 | F12: =+SUM('TB Feb''13'!J47:J52) -> 28187123 | G12: =+SUM('TB March''13'!J48:J53) -> 37983112 | H12: =+SUM('TB June''13'!J49:J54) -> 37654393 | I12: =+SUM('TB for 2013'!J57:J62) -> 4.5097972e+08 | K12: 1481
B13: 2.2. ຄ່າເສື່ອມມູນຄ່າສຸດທິຂອງເງິນລົງທຶນໃນຫຼັກຊັບ ແລະ ລາຍການອື່ນໆ | D13: 0 | E13: 0 | F13: 0 | G13: 0 | H13: 0 | I13: 0
B14: 2.3. ຂາດທຶນຈາກການຂາຍຊັບສົມບັດຄົງທີ່ | D14: 0 | E14: 0 | F14: 0 | G14: 0 | H14: 0 | I14: 0 | K14: 4506…
B15: 2.4. ກຳໄລຈາກການຂາຍຊັບສົມບັດຄົງທີ່ | D15: 0 | E15: 0 | F15: 0 | G15: 0 | H15: 0 | I15: 0
B16: 2.5. ສ່ວນປ່ຽນແປງໃນລາຍການດອກເບ້ຍ ແລະ ລາຍຮັບອື່ນໆຄ້າງຮັບ | D16: 0 | E16: 0 | F16: 0 | G16: 0 | H16: 0 | I16: 0
B17: 2.6. ສ່ວນປ່ຽນແປງໃນລາຍການດອກເບ້ຍ ແລະ ລາຍຈ່າຍອື່ນໆຄ້າງຈ່າຍ | D17: 0 | E17: 0 | F17: 0 | G17: 0 | H17: 0 | I17: 0
B18: ກ. ກະແສເງິນສົດສຸດທິຈາກກິດຈະກຳການດຳເນີນງານກ່ອນການປ່ຽນແປງໃນລາຍການຊັບສິນ ແລະ ໜີ້ສິນໝູນວຽນ | D18: =+D10+D11 -> 4182914.6 | E18: =+E10+E11 -> 2.8351969e+08 | F18: =+F10+F11 -> 4.1253235e+08 | G18: =+G10+G11 -> 38853011 | H18: =+H10+H11 -> 1.9884389e+08 | I18: =+I10+I11 -> 3.7214653e+09 | K18: 1+2
B19: 3. ການປ່ຽນແປງ (ເພີ່ມຂຶ້ນ) ຫຼື ຫຼຸດລົງ ໃນລາຍການຊັບສິນໝູນວຽນ | D19: =+D20+D21+D22+D23+D24+D25+D26+D27 -> -21876577 | E19: =+E20+E21+E22+E23+E24+E25+E26+E27 -> 1.1847e+10 | F19: =+F20+F21+F22+F23+F24+F25+F26+F27 -> 8.7998332e+09 | G19: =+G20+G21+G22+G23+G24+G25+G26+G27 -> 3.575521e+09 | H19: =+H20+H21+H22+H23+H24+H25+H26+H27 -> 2.8487901e+09 | I19: =+I20+I21+I22+I23+I24+I25+I26+I27 -> -2.0980819e+10 | N19: 9
B20: 3.1. ເງິນຝາກທະນາຄານ ແລະ ສະຖາບັນການເງິນ | D20: =-SUM('TB 2012'!I6:I25)/1000 -> -20185460 | E20: =-SUM('TB JAn''13'!I6:I24) -> 1.172383e+10 | F20: =-SUM('TB Feb''13'!I6:I24) -> 9.1610587e+09 | G20: =-SUM('TB March''13'!I6:I24) -> 4.4869567e+09 | H20: =-SUM('TB June''13'!I6:I25) -> 3.2601373e+09 | I20: =-SUM('TB for 2013'!I6:I25) -> -2.0271093e+10 | K20: 1121+1131
B21: 3.2. ເງິນລົງທຶນໄລຍະສັ້ນ | D21: =-('TB 2012'!I33+'TB 2012'!I34)/1000 -> -434990.2 | E21: =-SUM('TB JAn''13'!I31:I32) -> -1.550254e+08 | F21: =-SUM('TB Feb''13'!I31:I32) -> -4.332526e+08 | G21: =-SUM('TB March''13'!I32:I33) -> -261499400 | H21: =-SUM('TB June''13'!I33:I34) -> -1.976227e+08 | I21: =-SUM('TB for 2013'!I39:I40) -> -1.0555983e+09 | K21: 1302216+1302218
B22: 3.3. ໜີ້ຕ້ອງຮັບທາງການຄ້າ | D22: =-'TB 2012'!I30/1000 -> -54536.206 | E22: =-SUM('TB JAn''13'!I28) -> 56396718 | F22: =-SUM('TB Feb''13'!I28) -> -87819167 | G22: =-SUM('TB March''13'!I29) -> 90243338 | H22: =-'TB June''13'!I30 -> -9765615 | I22: =-SUM('TB for 2013'!I36) -> -368515318 | K22: 1201181
B23: 3.4. ໜີ້ຕ້ອງຮັບທາງທຸລະກຳຫຼັກຊັບ | D23: 0 | E23: 0 | F23: 0 | G23: 0 | H23: 0 | I23: 0 | K23: ບ/ຊ 120611+12311+123151+1241+1261
B24: 3.5. ໜີ້ຕ້ອງຮັບລະຫວ່າງບໍລິສັດໃນກຸ່ມ | D24: =-'TB 2012'!I31/1000 -> 23823.233 | E24: =-SUM('TB JAn''13'!I29) -> -139167192 | F24: =-SUM('TB Feb''13'!I29) -> 139167192 | G24: =-SUM('TB March''13'!I30) -> -759514740 | H24: =-SUM('TB June''13'!I31) -> 10467164 | I24: =-SUM('TB for 2013'!I37) -> -10142696 | K24: 1211110
B25: 3.6. ໜີ້ຕ້ອງຮັບອື່ນໆ | D25: =-('TB 2012'!I26+'TB 2012'!I32)/1000 -> -1027703.1 | E25: =-SUM('TB JAn''13'!I25+'TB JAn''13'!I30) -> 3.3382056e+08 | F25: =-SUM('TB Feb''13'!I25+'TB Feb''13'!I30) -> -32451481 | G25: =-SUM('TB March''13'!I25+'TB March''13'!I31) -> 7298891.9 | H25: =-SUM('TB June''13'!I26+'TB June''13'!I32) -> 38698630 | I25: =-('TB for 2013'!I32+'TB for 2013'!I38) -> 5.466529e+08 | K25: 1137111+1301720
B26: 3.7. ເຄື່ອງໃນສາງ | D26: 0 | E26: 0 | F26: 0 | G26: 0 | H26: 0 | I26: 0 | K26: ບ/ຊ 1371+1373+1376+1378-1379
B27: 3.8. ຊັບສິນໝູນວຽນອື່ນໆ | D27: =-SUM('TB 2012'!I35:I43)/1000-SUM('TB 2012'!I27:I29)/1000 -> -197710.1 | E27: =-SUM('TB JAn''13'!I26:I27)-SUM('TB JAn''13'!I33:I40) -> 27145528 | F27: =-SUM('TB Feb''13'!I26:I27)-SUM('TB Feb''13'!I33:I40) -> 53130620 | G27: =-SUM('TB March''13'!I26:I28)-SUM('TB March''13'!I34:I41) -> 12036143 | H27: =-SUM('TB June''13'!I27:I29)-SUM('TB June''13'!I35:I42) -> -2.5312468e+08 | I27: =-SUM('TB for 2013'!I33:I35)-SUM('TB for 2013'!I41:I50) -> 1.7787792e+08 | K27: 1138100+1138810+1138830+1360000+1361100+1361300+1361500+1362100+1388110+1388120+1388170+1388180
B28: ຂ. ກະແສເງິນສົດສຸດທິຈາກການປ່ຽນແປງໃນຊັບສິນໝູນວຽນ | D28: =+D19 -> -21876577 | E28: =+E19 -> 1.1847e+10 | F28: =+F19 -> 8.7998332e+09 | G28: =+G19 -> 3.575521e+09 | H28: =+H19 -> 2.8487901e+09 | I28: =+I19 -> -2.0980819e+10 | L28: =+G28+'TB March''13'!L41 -> 0 | M28: ok | N28: =+G28+G36 -> -74581361
B29: 4. ການປ່ຽນແປງ ເພີ່ມຂຶ້ນ ຫຼື (ຫຼຸດລົງ) ໃນລາຍການໜີ້ສິນໝູນວຽນ | D29: =+D30+D31+D32+D33+D34+D35 -> 17872192 | E29: =+E30+E31+E32+E33+E34+E35 -> -1.2124988e+10 | F29: =+F30+F31+F32+F33+F34+F35 -> -9.2144256e+09 | G29: =+G30+G31+G32+G33+G34+G35 -> -3.6501023e+09 | H29: =+H30+H31+H32+H33+H34+H35 -> -3.4617652e+09 | I29: =+I30+I31+I32+I33+I34+I35 -> 1.6818077e+10 | L29: =+'TB March''13'!L71-'Cash flow statement '!G36 -> 0 | N29: =+N28+G18 -> -35728350
B30: 4.1. ໜີ້ຕ້ອງສົ່ງທາງການຄ້າ | D30: 0 | E30: 0 | F30: 0 | G30: 0 | H30: 0 | I30: 0 | N30: =+N29+G42 -> -35663705
B31: 4.2. ໜີ້ຕ້ອງສົ່ງທາງທຸລະກຳຫຼັກຊັບ | D31: =SUM('TB 2012'!J59:J62)/1000 -> 15911349 | E31: =+SUM('TB JAn''13'!J54:J57) -> -1.1983988e+10 | F31: =+SUM('TB Feb''13'!J54:J57) -> -7856401088 | G31: =+SUM('TB March''13'!J55:J58) -> -3868953821 | H31: =+SUM('TB June''13'!J56:J59) -> -3296695737 | I31: =+SUM('TB for 2013'!J65:J69) -> 1.6862262e+10 | K31: 2344100+2344200+2344600+2344700
B32: 4.3. ໜີ້ຕ້ອງສົ່ງລະຫວ່າງບໍລິສັດໃນກຸ່ມ | D32: ='TB 2012'!J57/1000 -> 53391.814 | E32: =+SUM('TB JAn''13'!J53) -> -56406512 | F32: =+SUM('TB Feb''13'!J53) -> 84359070 | G32: =+SUM('TB March''13'!J54) -> -85190134 | H32: =+SUM('TB June''13'!J55) -> 8130534 | I32: =+SUM('TB for 2013'!J64) -> 237683525 | K32: 2211110
B33: 4.4. ອາກອນກຳໄລຄ້າງຈ່າຍ | D33: ='TB 2012'!J63/1000 -> 1455561.6 | E33: =+SUM('TB JAn''13'!J58) -> 0 | F33: =+'TB Feb''13'!J58 -> -1.4555616e+09 | G33: =+'TB March''13'!J59 -> 2.1782006e+08 | H33: =+'TB June''13'!J60 -> -0.21999999 | I33: =+SUM('TB for 2013'!J70) -> -1.0781391e+09 | K33: 2361110
B34: 4.5. ໜີ້ຕ້ອງສົ່ງອື່ນໆ | D34: =SUM('TB 2012'!J64:J72)/1000 -> 134141.94 | E34: =+SUM('TB JAn''13'!J59:J67) -> -84593623 | F34: =+SUM('TB Feb''13'!J59:J67) -> 40218052 | G34: =+SUM('TB March''13'!J60:J68) -> 86221580 | H34: =+SUM('TB June''13'!J61:J69)-SUM('TB June''13'!I61:I69) -> 82961781 | I34: =+SUM('TB for 2013'!J71:J79) -> -1.3474711e+08 | K34: 2361120+2361130+2361140+2361410+2361420+2361430+2361440+2361830+2361831
B35: 4.6. ໜີ້ສິນໝູນວຽນອື່ນໆ | D35: =SUM('TB 2012'!J73:J76)/1000 -> 317746.77 | E35: =+SUM('TB JAn''13'!J68:J70) -> 0 | F35: =+SUM('TB Feb''13'!J68:J70) -> -27040033 | G35: =+SUM('TB March''13'!J69:J71) -> 0 | H35: =+SUM('TB June''13'!J70:J72) -> -2.5616179e+08 | I35: =+SUM('TB for 2013'!J80:J82) -> 9.3101849e+08 | K35: 2363682+2363683+2363684
B36: ຄ. ກະແສເງິນສົດສຸດທິຈາກການປ່ຽນແປງໃນໜີ້ສິນໝູນວຽນ | D36: =+D29 -> 17872192 | E36: =+E29 -> -1.2124988e+10 | F36: =+F29 -> -9.2144256e+09 | G36: =+G29 -> -3.6501023e+09 | H36: =+H29 -> -3.4617652e+09 | I36: =+I29 -> 1.6818077e+10 | J36: ok for the formula | L36: =+G36-'TB March''13'!L71 -> 0 | M36: ok
B37: ກະແສເງິນສົດສຸດທິຈາກກິດຈະກຳດຳເນີນງານ | D37: =+D18+D28+D36 -> 178529.32 | E37: =+E18+E28+E36 -> 5532000 | F37: =+F18+F28+F36 -> -2060000 | G37: =+G18+G28+G36 -> -35728350 | H37: =+H18+H28+H36 -> -414131207 | I37: =+I18+I28+I36 -> -4.4127616e+08
A38: II | B38: ​ກະແສເງິນສົດຈາກກິດຈະກໍາລົງທຶນ
B39: 1. ສ່ວນ (ເພີ່ມຂຶ້ນ) ຫຼື ຫຼຸດລົງ ໃນລາຍການເງິນລົງທຶນໄລຍະຍາວ | D39: 0 | E39: 0 | F39: 0 | G39: 0 | H39: 0 | I39: 0
B40: 2. ສ່ວນ (ເພີ່ມຂຶ້ນ) ຫຼື ຫຼຸດລົງ ໃນລາຍໜີ້ຕ້ອງຮັບໄລຍະຍາວ ແລະ ຊັບສິນໄລຍະຍາວອື່ນໆ | D40: 0 | E40: 0 | F40: 0 | G40: 0 | H40: 0 | I40: 0
...

Sheet TB 2012
A1: ສາທາລະນະລັດ ປະຊາທິປະໄຕ ປະຊາຊົນລາວ | B1: ສັນຕິພາບ ເອກະລາດ ປະຊາທິປະໄຕ ເອກະພາບ ວັດທະນາຖາວອນ | F1: 2012
A2: ບໍລິສັດຫຼັກຊັບ ທຄຕລ-ກທ ຈຳກັດ_x000D_ ຊັ້ນ7, ຕຶກຕະຫຼາກຫຼັກຊັບລາວ, ຖະໜົນກຳແພງເມືອງ_x000D_ +856-21-265477+856-21-265488
C3: Opening | E3: Movement | G3: Balance | I3: Change
C4: ໜີ້ | D4: ມີ | E4: ໜີ້ | F4: ມີ | G4: ໜີ້ | H4: ມີ | I4: ໜີ້ | J4: ມີ
A5: 1101100 | B5: ເງິນສົດໃນຄັງ " HO " ກີບ | C5: 10000000 | D5: 0 | E5: 1.4693651e+08 | F5: 1.5246851e+08 | G5: 4468000 | H5: 0 | I5: =G5-C5 -> -5532000 | L5: =+E5-F5 -> -5532000
A6: 1121110 | B6: ບັນຊີທຶນຈົດທະບຽນຂອງ ທຄຕລ-ກທ ຈຳກັດ ( ກີບ ) | C6: 7.2281614e+10 | D6: 0 | E6: 0 | F6: 70000010000 | G6: 2.2816035e+09 | H6: 0 | I6: =G6-C6 -> -70000010000 | L6: =+E6-F6 -> -70000010000
A7: 1131110 | B7: ບັນຊີກະແສລາຍວັນ ທຄຕລ: 010.0.11.00.24740 ( ກີບ ) | C7: 652607.74 | D7: 0 | E7: 2.6829711e+08 | F7: 268812113 | G7: 137607.24 | H7: 0 | I7: =G7-C7 -> -515000.5 | L7: =+E7-F7 -> -515000.5
A8: 1131111 | B8: ບັນຊີກະແສລາຍວັນ ທຄຕລ: 010.7.11.02.08233 ( ບາດ ) | C8: 713249.55 | D8: 0 | E8: 1196931.5 | F8: 121655.66 | G8: 1788525.4 | H8: 0 | I8: =G8-C8 -> 1075275.8 | L8: =+E8-F8 -> 1075275.8
A9: 1131112 | B9: ບັນຊີກະແສລາຍວັນ ທຄຕລ: 010.9.11.01.19243 ( ໂດລ່າ ) | C9: 1641620.4 | D9: 0 | E9: 69481101 | F9: 69528404 | G9: 1594317.1 | H9: 0 | I9: =G9-C9 -> -47303.28 | L9: =+E9-F9 -> -47303.28
A10: 1131113 | B10: ບັນຊີກະແສລາຍວັນ ທຄຕລ Proprietary AC: 010.4.19.00.00009 ( ກີບ ) | C10: 92595445 | D10: 0 | E10: 154946789255 | F10: 154744754910 | G10: 294629790 | H10: 0 | I10: =G10-C10 -> 202034345 | L10: =+E10-F10 -> 202034345
A11: 1131115 | B11: ບັນຊີກະແສລາຍວັນ ທຄຕລ Aggregate AC: 010.4.19.00.00010 ( ກີບ ) | C11: 39741098167 | D11: 0 | E11: 669329114813 | F11: 653419265157 | G11: 55650947823 | H11: 0 | I11: =G11-C11 -> 15909849656 | L11: =+E11-F11 -> 15909849656
A12: 1131116 | B12: ບັນຊີກະແສລາຍວັນ ທຄຕລ for ETL staff IPO AC: 010.9.00.00001 ( ກີບ ) | C12: 100000 | D12: 0 | E12: 0 | F12: 0 | G12: 100000 | H12: 0 | I12: =G12-C12 -> 0
A13: 1131117 | B13: ບັນຊີກະແສລາຍວັນ ທຄຕລ ສຳລັບການຈອງ RO EDL-Gen :010.8.19.00.00012 LAk | C13: 0 | D13: 0 | E13: 405151388000 | F13: 405151388000 | G13: 0 | H13: 0 | I13: =G13-C13 -> 0
A14: 1131119 | B14: ບັນຊີກະແສລາຍວັນ ທຄຕລ ສຳລັບການ​ຈອງ PO EDL: 010.5.19.00.00013 Lak | C14: 0 | D14: 0 | E14: 1.7653324e+10 | F14: 1.7653324e+10 | G14: 0 | H14: 0 | I14: =G14-C14 -> 0
A15: 1131120 | B15: ບັນຊີກະແສລາຍວັນ ທຄຕລ ສຳລັບການ​ຈອງ PO EDL: 010.4.19.01.00006 USD | C15: 0 | D15: 0 | E15: 1.7085271e+11 | F15: 1.7085271e+11 | G15: 0 | H15: 0 | I15: =G15-C15 -> 0 | L15: =+SUM(I5:I20) -> -4.4820072e+10 | M15: OK
A16: 1131121 | B16: ບັນຊີກະແສລາຍວັນ ເອຊີລີດາ 123359-1-1-101 | C16: 0 | D16: 0 | E16: 1000000 | F16: 0 | G16: 1000000 | H16: 0 | I16: =G16-C16 -> 1000000 | L16: =+L15-L21 -> 0
A17: 1131130 | B17: ບັນຊີຝາກປະຢັດທີ່ ທຄຕລ: 013.2.12.00.00036 ກີບ | C17: 2.2618014e+09 | D17: 0 | E17: 1.1798555e+11 | F17: 1.10998e+11 | G17: 9.2493495e+09 | H17: 0 | I17: =G17-C17 -> 6.9875481e+09
A18: 1131131 | B18: ບັນຊີຝາກປະຢັດທີ່ ທຄຕລ: 013.9.12.01.00001 ( ໂດລ່າ ) | C18: 8.9027339e+08 | D18: 0 | E18: 3.5927276e+10 | F18: 3.6787536e+10 | G18: 30012667 | H18: 0 | I18: =G18-C18 -> -8.6026073e+08 | L18: =+SUM(C5:C20) -> 1.1663937e+11 | M18: Cash for 2011
A19: 1131134 | B19: ບັນຊີຝາກປະຢັດທີ່ ທສກ: 0402.0.00.220130 ( ກີບ ) | C19: 1358879432 | D19: 0 | E19: 2110287566 | F19: 0 | G19: 3469166998 | H19: 0 | I19: =G19-C19 -> 2110287566 | L19: =+SUM(G5:G20) -> 7.1819297e+10 | M19: Cash for 2012
A20: 1131137 | B20: ບັນຊີຝາກປະຍັດ ທຄຕລ-ກທ ທີ່ ເອຊີລີດາ 123359-1-0-0101 ( ກີບ ) | C20: 0 | D20: 0 | E20: 3.5834499e+10 | F20: 35000000000 | G20: 8.3449851e+08 | H20: 0 | I20: =G20-C20 -> 8.3449851e+08
A21: 1131153 | B21: ບັນຊີຝາກມີກຳນົດທີ່ ທສກ: 0402.0402.00.2131315.47.00000003 ( ກີບ ) | C21: 20000000000 | D21: 0 | E21: 0 | F21: 0 | G21: 20000000000 | H21: 0 | I21: =G21-C21 -> 0 | L21: =+L19-L18 -> -4.4820072e+10 | M21: Change for the year
A22: 1131154 | B22: ບັນຊີຝາກມີກຳນົດທີ່ ທສກ: 0402.0402.00.2131315.47.00000004 ( ກີບ ) | C22: 0 | D22: 0 | E22: 25000000000 | F22: 0 | G22: 25000000000 | H22: 0 | I22: =G22-C22 -> 25000000000 | L22: =+L18 -> 1.1663937e+11 | M22: Cash and cash equarvalent for the last year / beginning for the year
A23: 1131156 | B23: ບັນຊີຝາກມີກຳນົດທີ່ Sacom Bank: 40.000006310.8 ( ກີບ ) | C23: 0 | D23: 0 | E23: 30000000000 | F23: 30000000000 | G23: 0 | H23: 0 | I23: =G23-C23 -> 0 | L23: =+SUM(L21:L22) -> 7.1819297e+10
A24: 1131159 | B24: ບັນຊີຝາກມີກຳນົດທີ່ ST Bank: 010.5.35.00.08899 ( ກີບ ) | C24: 0 | D24: 0 | E24: 5000000000 | F24: 0 | G24: 5000000000 | H24: 0 | I24: =G24-C24 -> 5000000000
A25: 1131162 | B25: ບັນຊີເງິນຝາກມີກຳນົດ ທີ່ ທະນາຄານ ເອຊີລີດາ ( ກີບ ) | C25: 0 | D25: 0 | E25: 35000000000 | F25: 0 | G25: 35000000000 | H25: 0 | I25: =G25-C25 -> 35000000000
A26: 1137111 | B26: ດອກເບ້ຍຝາກມີກຳນົດ ຄ້າງຮັບ 1 ປີລົງມາ | C26: 169863014 | D26: 0 | E26: 5824469182 | F26: 5.3326256e+09 | G26: 6.6170662e+08 | H26: 0 | I26: =G26-C26 -> 4.9184361e+08
A27: 1138100 | B27: ກອງທຶນປົກປ້ອງຄວາມສ່ຽງໃນການຊຳລະສະສາງ | C27: 136517614 | D27: 0 | E27: 18938509 | F27: 342 | G27: 155455781 | H27: 0 | I27: =G27-C27 -> 18938167
A28: 1138810 | B28: ເງິນມັດຈຳຄ່າເຊົ່າ | C28: 11888910 | D28: 0 | E28: 0 | F28: 0 | G28: 11888910 | H28: 0 | I28: =G28-C28 -> 0
A29: 1138830 | B29: ເງິນມັດຈຳອື່ນໆ | C29: 0 | D29: 0 | E29: 4449332 | F29: 4449332 | G29: 0 | H29: 0 | I29: =G29-C29 -> 0
A30: 1201181 | B30: ລູກໜີ້ຊື້ຫຼັກຊັບຕາມຄຳສັ່ງຊື້-ບັນຊີເງິນສົດ | C30: 4284683 | D30: 0 | E30: 23279067826 | F30: 23224531620 | G30: 58820889 | H30: 0 | I30: =G30-C30 -> 54536206
A31: 1211110 | B31: ລູກໜີ້ບັນຊີຊື້-ຂາຍຫຼັກຊັບລະຫວ່າງບ/ສ ກັບ LSX | C31: 23823233 | D31: 0 | E31: 5742141356 | F31: 5765964589 | G31: 0 | H31: 0 | I31: =G31-C31 -> -23823233
A32: 1301720 | B32: ຄ່າທີ່ປຶກສາຄ້າງຮັບ | C32: 0 | D32: 0 | E32: 1024442620 | F32: 488583100 | G32: 535859520 | H32: 0 | I32: =G32-C32 -> 535859520 | L32: =-SUM('TB 2012'!I35:I43)/1000-SUM('TB 2012'!I27:I29)/1000 -> -197710.1
A33: 1302216 | B33: ເງິນລົງທືນຊົ່ວຄາວຫຼັກຊັບ-ເພື່ອຄ້າ-Port Trading | C33: 117180970 | D33: 0 | E33: 5.5465994e+08 | F33: 197620970 | G33: 4.7421994e+08 | H33: 0 | I33: =G33-C33 -> 3.5703897e+08
A34: 1302218 | B34: ຄ່າປັບມູນຄ່າເງິນລົງທືນຊົ່ວຄາວຫຼັກຊັບ-ເພື່ອຄ້າ-Port trading | C34: 0 | D34: 37250970 | E34: 4.0190649e+08 | F34: 3.2395527e+08 | G34: 40700260 | H34: 0 | I34: =G34-C34+D34 -> 77951230 | L34: =+E34-F34 -> 77951230
A35: 1360000 | B35: ລູກໜີ້ອື່ນໆ | C35: 61100181 | D35: 0 | E35: 4846066 | F35: 59977664 | G35: 5968583 | H35: 0 | I35: =G35-C35 -> -55131598 | L35: =+E35-F35 -> -55131598
A36: 1361100 | B36: ອາກອນກຳໄລມອບລ່ວງໜ້າ | C36: 27761356 | D36: 0 | E36: 99581906 | F36: 1.2734326e+08 | G36: 0 | H36: 0 | I36: =G36-C36 -> -27761356 | L36: =+E36-F36 -> -27761356
A37: 1361300 | B37: ອາກອນອື່ນໆທີ່ຕ້ອງຮັບຄືນ | C37: 27382364 | D37: 0 | E37: 6845600 | F37: 34227964 | G37: 0 | H37: 4.7683716e-09 | I37: =G37-C37 -> -27382364 | L37: =+E37-F37 -> -27382364
A38: 1361500 | B38: ລູນໜີ້ ເຄທີຂີມີໂກ້ ຈຳກັດ | C38: 0 | D38: 0 | E38: 94848000 | F38: 94848000 | G38: 0 | H38: 0 | I38: =G38-C38 -> 0 | L38: =+E38-F38 -> 0
A39: 1362100 | B39: ເງິນຈ່າຍລ່ວງໜ້າເພື່ອເຄື່ອນໄຫວວຽກງານ | C39: 36400000 | D39: 0 | E39: 243979076 | F39: 279879076 | G39: 500000 | H39: 0 | I39: =G39-C39 -> -35900000 | L39: =+E39-F39 -> -35900000
A40: 1388110 | B40: ຄ່າເຊົ່າຈ່າຍລ່ວງໜ້າ | C40: 23950902 | D40: 0 | E40: 9.7255238e+08 | F40: 5.5573423e+08 | G40: 4.4076906e+08 | H40: 0 | I40: =G40-C40 -> 4.1681815e+08 | L40: =+E40-F40 -> 4.1681815e+08
...

Sheet TB JAn'13
A1: ສາທາລະນະລັດ ປະຊາທິປະໄຕ ປະຊາຊົນລາວ | B1: ສັນຕິພາບ ເອກະລາດ ປະຊາທິປະໄຕ ເອກະພາບ ວັດທະນາຖາວອນ
D3: ໃບດູນດ່ຽງປະຈຳເດືອນ | E3: ເດືອນ 01/2013 | F3: ບໍລິສັດຫຼັກຊັບ ທຄຕລ-ກທ ຈຳກັດ_x000D_ ຊັ້ນ7, ຕຶກຕະຫຼາກຫຼັກຊັບລາວ, ຖະໜົນກຳແພງເມືອງ_x000D_ +856-21-265477+856-21-265488
C4: ໜີ້ | D4: ມີ | E4: ໜີ້ | F4: ມີ | G4: ໜີ້ | H4: ມີ
A5: 1101100 | B5: ເງິນສົດໃນຄັງ " HO " ກີບ | C5: 4468000 | D5: 0 | E5: 16629470 | F5: 11097470 | G5: 10000000 | H5: 0 | I5: =+G5-C5 -> 5532000 | J5: =+H5-D5 -> 0
A6: 1121110 | B6: ບັນຊີທຶນຈົດທະບຽນຂອງ ທຄຕລ-ກທ ຈຳກັດ ( ກີບ ) | C6: 2.2816035e+09 | D6: 0 | E6: 0 | F6: 0 | G6: 2.2816035e+09 | H6: 0 | I6: =+G6-C6 -> 0 | J6: =+H6-D6 -> 0
A7: 1131110 | B7: ບັນຊີກະແສລາຍວັນ ທຄຕລ: 010.0.11.00.24740 ( ກີບ ) | C7: 137607.24 | D7: 0 | E7: 0 | F7: 0 | G7: 137607.24 | H7: 0 | I7: =+G7-C7 -> 0 | J7: =+H7-D7 -> 0
A8: 1131111 | B8: ບັນຊີກະແສລາຍວັນ ທຄຕລ: 010.7.11.02.08233 ( ບາດ ) | C8: 1788525.4 | D8: 0 | E8: 1.3757003e+08 | F8: 137083.21 | G8: 1.3922147e+08 | H8: 0 | I8: =+G8-C8 -> 1.3743295e+08 | J8: =+H8-D8 -> 0
A9: 1131112 | B9: ບັນຊີກະແສລາຍວັນ ທຄຕລ: 010.9.11.01.19243 ( ໂດລ່າ ) | C9: 1594317.1 | D9: 0 | E9: 0 | F9: 9604.32 | G9: 1584712.8 | H9: 0 | I9: =+G9-C9 -> -9604.32 | J9: =+H9-D9 -> 0
A10: 1131113 | B10: ບັນຊີກະແສລາຍວັນ ທຄຕລ Proprietary AC: 010.4.19.00.00009 ( ກີບ ) | C10: 294629790 | D10: 0 | E10: 2491046499 | F10: 2562293702 | G10: 223382587 | H10: 0 | I10: =+G10-C10 -> -71247203 | J10: =+H10-D10 -> 0
A11: 1131115 | B11: ບັນຊີກະແສລາຍວັນ ທຄຕລ Aggregate AC: 010.4.19.00.00010 ( ກີບ ) | C11: 55650947823 | D11: 0 | E11: 8187959711 | F11: 20285288714 | G11: 43553618820 | H11: 0 | I11: =+G11-C11 -> -12097329003 | J11: =+H11-D11 -> 0
A12: 1131116 | B12: ບັນຊີກະແສລາຍວັນ ທຄຕລ for ETL staff IPO AC: 010.9.00.00001 ( ກີບ ) | C12: 100000 | D12: 0 | E12: 0 | F12: 0 | G12: 100000 | H12: 0 | I12: =+G12-C12 -> 0 | J12: =+H12-D12 -> 0
A13: 1131117 | B13: ບັນຊີກະແສລາຍວັນ ທຄຕລ ສຳລັບການຈອງ RO EDL-Gen :010.8.19.00.00012 LAk | C13: 0 | D13: 0 | E13: 0 | F13: 0 | G13: 0 | H13: 0 | I13: =+G13-C13 -> 0 | J13: =+H13-D13 -> 0
A14: 1131119 | B14: ບັນຊີກະແສລາຍວັນ ທຄຕລ ສຳລັບການ​ຈອງ PO EDL: 010.5.19.00.00013 Lak | C14: 3.8146973e-06 | D14: 0 | E14: 0 | F14: 0 | G14: 3.8146973e-06 | H14: 0 | I14: =+G14-C14 -> 0 | J14: =+H14-D14 -> 0
A15: 1131120 | B15: ບັນຊີກະແສລາຍວັນ ທຄຕລ ສຳລັບການ​ຈອງ PO EDL: 010.4.19.01.00006 USD | C15: 0 | D15: 1.3425946e-05 | E15: 0 | F15: 0 | G15: 0 | H15: 1.3425946e-05 | I15: =+G15-C15 -> 0 | J15: =+H15-D15 -> 0
A16: 1131121 | B16: ບັນຊີກະແສລາຍວັນ ເອຊີລີດາ 123359-1-1-101 | C16: 1000000 | D16: 0 | E16: 0 | F16: 0 | G16: 1000000 | H16: 0 | I16: =+G16-C16 -> 0 | J16: =+H16-D16 -> 0
... A74: 3908000 | B74: ຜົນໄດ້ຮັບ ລໍຖ້າຮັບຮອງ | C74: 0 | D74: 0 | E74: 0 | F74: 3.7642156e+09 | G74: 0 | H74: 3.7642156e+09 | I74: =+G74-C74 -> 0 | J74: =+H74-D74 -> 3.7642156e+09
B75: Total | C75: =SUM(C5:C74) -> 1.6298527e+11 | D75: =SUM(D5:D74) -> 1.6298527e+11 | E75: =SUM(E5:E74) -> 4.2050835e+10 | F75: =SUM(F5:F74) -> 4.1806911e+10 | G75: =SUM(G5:G74) -> 1.5114381e+11 | H75: =SUM(H5:H74) -> 1.5089988e+11 | I75: =SUM(I5:I74) -> -1.1841468e+10 | J75: =SUM(J5:J74) -> -1.2085392e+10
B76: Net profit | D76: =+C75-D75 -> 0 | F76: =+E75-F75 -> 2.4392347e+08 | H76: =+G75-H75 -> 2.4392347e+08 | J76: =+I75-J75 -> 2.4392347e+08 | L76: =+J76-H76 -> -1.335144e-05
C79: ໜີ້ | D79: ມີ | E79: ໜີ້ | F79: ມີ | G79: ໜີ້ | H79: ມີ | I79: Net profit
A80: 4102730 | B80: ຄ່າບໍລິການເຊົ່າລະບົບເທີມີນໍ່ LSX | C80: 0 | D80: 0 | E80: 21158280 | F80: 0 | G80: 21158280 | H80: 0 | I80: =+F80-E80 -> -21158280
A81: 4102731 | B81: ຄ່າບໍລິການເຊົ່າລະບົບດິດສເປຣເຢີ່ LSX | C81: 0 | D81: 0 | E81: 2566080 | F81: 0 | G81: 2566080 | H81: 0 | I81: =+F81-E81 -> -2566080
A82: 4108210 | B82: ຄ່າທຳນຽມທະນາຄານ ( ຈ່າຍ ) | C82: 0 | D82: 0 | E82: 369951.21 | F82: 0 | G82: 369951.21 | H82: 0 | I82: =+F82-E82 -> -369951.21
A83: 4201100 | B83: ເງິນເດືອນພະນັກງານໃນການຈັດຕັ້ງ | C83: 0 | D83: 0 | E83: 159159677 | F83: 0 | G83: 159159677 | H83: 0 | I83: =+F83-E83 -> -159159677
A84: 4201400 | B84: ເງິນເພີ່ມໂມງ | C84: 0 | D84: 0 | E84: 47351378 | F84: 0 | G84: 47351378 | H84: 0 | I84: =+F84-E84 -> -47351378
A85: 4202200 | B85: ລາຍຈ່າຍຄ່າປະກັນໄພພະນັກງານ | C85: 0 | D85: 0 | E85: 10198798 | F85: 0 | G85: 10198798 | H85: 0 | I85: =+F85-E85 -> -10198798
A86: 4202220 | B86: ລາຍຈ່າຍຄ່ານ້ຳມັນລົດພະນັກງານ | C86: 0 | D86: 0 | E86: 17283871 | F86: 0 | G86: 17283871 | H86: 0 | I86: =+F86-E86 -> -17283871
A87: 4202800 | B87: ລາຍຈ່າຍສະຫວັດດີການພະນັກງານອື່ນໆ | C87: 0 | D87: 0 | E87: 14000000 | F87: 0 | G87: 14000000 | H87: 0 | I87: =+F87-E87 -> -14000000
A88: 4202811 | B88: ລາຍຈ່າຍເບ້ຍປະຊູມສະພາບໍລິຫານ | C88: 0 | D88: 0 | E88: 10736842 | F88: 0 | G88: 10736842 | H88: 0 | I88: =+F88-E88 -> -10736842
A89: 4203100 | B89: ສຳມະນາ ແລະຝຶກອົບຮົມພາຍໃນປະເທດ | C89: 0 | D89: 0 | E89: 5000000 | F89: 0 | G89: 5000000 | H89: 0 | I89: =+F89-E89 -> -5000000
A90: 4208400 | B90: ຄ່າອາຫານຈັດປະຂູມພະນັກງານ | C90: 0 | D90: 0 | E90: 4087400 | F90: 0 | G90: 4087400 | H90: 0 | I90: =+F90-E90 -> -4087400
A91: 4208500 | B91: ນ້ຳດື່ມພະນັກງານ | C91: 0 | D91: 0 | E91: 2752000 | F91: 0 | G91: 2752000 | H91: 0 | I91: =+F91-E91 -> -2752000
... A136: 5508400 | B136: ລາຍຮັບອື່ນໆ | C136: 0 | D136: 0 | E136: 0 | F136: 2000 | G136: 0 | H136: 2000 | I136: =+F136-E136 -> 2000
B137: ລວມມູນຄ່າ | C137: =SUM(C80:C136) -> 0 | D137: =SUM(D80:D136) -> 0 | E137: =SUM(E80:E136) -> 6.6914401e+08 | F137: =SUM(F80:F136) -> 9.1306748e+08 | G137: =SUM(G80:G136) -> 6.4342647e+08 | H137: =SUM(H80:H136) -> 8.8734993e+08 | J137: 0 | K137: -5.859375e-05 | L137: ນະຄອນຫຼວງວຽງຈັນ ວັນທີ : ......../......../............ , | M137: ຜູ້ອຳນວຍການ | N137: ທີ່ປຶກສາບັນຊີ | O137: ພະນັກງານບັນຊີ | P137: ຜູ້ສັງລວມ | Q137: ............…………………...... | R137: ...…………………………..
A138: 1 | B138: Net Profit | E138: =+F137-E137 -> 2.4392347e+08 | G138: =+H137-G137 -> 2.4392347e+08 | I138: =SUM(I80:I136) -> 2.4392347e+08

Sheet TB Feb'13
A1: ສາທາລະນະລັດ ປະຊາທິປະໄຕ ປະຊາຊົນລາວ | B1: ສັນຕິພາບ ເອກະລາດ ປະຊາທິປະໄຕ ເອກະພາບ ວັດທະນາຖາວອນ
D3: ໃບດູນດ່ຽງປະຈຳເດືອນ | E3: ເດືອນ 02/2013 | F3: ບໍລິສັດຫຼັກຊັບ ທຄຕລ-ກທ ຈຳກັດ_x000D_ ຊັ້ນ7, ຕຶກຕະຫຼາກຫຼັກຊັບລາວ, ຖະໜົນກຳແພງເມືອງ_x000D_ +856-21-265477+856-21-265488
C4: ໜີ້ | D4: ມີ | E4: ໜີ້ | F4: ມີ | G4: ໜີ້ | H4: ມີ
A5: 1101100 | B5: ເງິນສົດໃນຄັງ " HO " ກີບ | C5: 10000000 | D5: 0 | E5: 6084000 | F5: 6084000 | G5: 10000000 | H5: 0 | I5: =+G5-C5 -> 0 | J5: =+H5-D5 -> 0
A6: 1121110 | B6: ບັນຊີທຶນຈົດທະບຽນຂອງ ທຄຕລ-ກທ ຈຳກັດ ( ກີບ ) | C6: 2.2816035e+09 | D6: 0 | E6: 0 | F6: 0 | G6: 2.2816035e+09 | H6: 0 | I6: =+G6-C6 -> 0 | J6: =+H6-D6 -> 0
A7: 1131110 | B7: ບັນຊີກະແສລາຍວັນ ທຄຕລ: 010.0.11.00.24740 ( ກີບ ) | C7: 137607.24 | D7: 0 | E7: 0 | F7: 0 | G7: 137607.24 | H7: 0 | I7: =+G7-C7 -> 0 | J7: =+H7-D7 -> 0
A8: 1131111 | B8: ບັນຊີກະແສລາຍວັນ ທຄຕລ: 010.7.11.02.08233 ( ບາດ ) | C8: 1.3922147e+08 | D8: 0 | E8: 0 | F8: 1512764.8 | G8: 1.3770871e+08 | H8: 0 | I8: =+G8-C8 -> -1512764.8 | J8: =+H8-D8 -> 0
A9: 1131112 | B9: ບັນຊີກະແສລາຍວັນ ທຄຕລ: 010.9.11.01.19243 ( ໂດລ່າ ) | C9: 1584712.8 | D9: 0 | E9: 0 | F9: 56448.14 | G9: 1528264.7 | H9: 0 | I9: =+G9-C9 -> -56448.14 | J9: =+H9-D9 -> 0
A10: 1131113 | B10: ບັນຊີກະແສລາຍວັນ ທຄຕລ Proprietary AC: 010.4.19.00.00009 ( ກີບ ) | C10: 223382587 | D10: 0 | E10: 4208520969 | F10: 4222432666 | G10: 209470890 | H10: 0 | I10: =+G10-C10 -> -13911697 | J10: =+H10-D10 -> 0
A11: 1131115 | B11: ບັນຊີກະແສລາຍວັນ ທຄຕລ Aggregate AC: 010.4.19.00.00010 ( ກີບ ) | C11: 43553618820 | D11: 0 | E11: 14707025363 | F11: 22424890783 | G11: 35835753400 | H11: 0 | I11: =+G11-C11 -> -7717865420 | J11: =+H11-D11 -> 0
A12: 1131116 | B12: ບັນຊີກະແສລາຍວັນ ທຄຕລ for ETL staff IPO AC: 010.9.00.00001 ( ກີບ ) | C12: 100000 | D12: 0 | E12: 0 | F12: 0 | G12: 100000 | H12: 0 | I12: =+G12-C12 -> 0 | J12: =+H12-D12 -> 0
A13: 1131117 | B13: ບັນຊີກະແສລາຍວັນ ທຄຕລ ສຳລັບການຈອງ RO EDL-Gen :010.8.19.00.00012 LAk | C13: 0 | D13: 0 | E13: 0 | F13: 0 | G13: 0 | H13: 0 | I13: =+G13-C13 -> 0 | J13: =+H13-D13 -> 0
A14: 1131119 | B14: ບັນຊີກະແສລາຍວັນ ທຄຕລ ສຳລັບການ​ຈອງ PO EDL: 010.5.19.00.00013 Lak | C14: 3.8146973e-06 | D14: 0 | E14: 0 | F14: 0 | G14: 3.8146973e-06 | H14: 0 | I14: =+G14-C14 -> 0 | J14: =+H14-D14 -> 0
A15: 1131120 | B15: ບັນຊີກະແສລາຍວັນ ທຄຕລ ສຳລັບການ​ຈອງ PO EDL: 010.4.19.01.00006 USD | C15: 0 | D15: 1.3425946e-05 | E15: 0 | F15: 0 | G15: 0 | H15: 1.3425946e-05 | I15: =+G15-C15 -> 0 | J15: =+H15-D15 -> 0
A16: 1131121 | B16: ບັນຊີກະແສລາຍວັນ ເອຊີລີດາ 123359-1-1-101 | C16: 1000000 | D16: 0 | E16: 0 | F16: 0 | G16: 1000000 | H16: 0 | I16: =+G16-C16 -> 0 | J16: =+H16-D16 -> 0
... A74: 3908000 | B74: ຜົນໄດ້ຮັບ ລໍຖ້າຮັບຮອງ | C74: 0 | D74: 3.7642156e+09 | E74: 0 | F74: 0 | G74: 0 | H74: 3.7642156e+09 | I74: =+G74-C74 -> 0 | J74: =+H74-D74 -> 0
C75: =SUM(C5:C74) -> 1.5114381e+11 | D75: =SUM(D5:D74) -> 1.5089988e+11 | E75: =SUM(E5:E74) -> 5.2954219e+10 | F75: =SUM(F5:F74) -> 5.2569874e+10 | G75: =SUM(G5:G74) -> 1.4234191e+11 | H75: =SUM(H5:H74) -> 1.4171364e+11 | I75: =SUM(I5:I74) -> -8.8018932e+09 | J75: =SUM(J5:J74) -> -9.1862385e+09
D76: =+C75-D75 -> 2.4392347e+08 | F76: =+E75-F75 -> 3.8434523e+08 | H76: =+G75-H75 -> 6.2826869e+08 | J76: =+I75-J75 -> 3.8434523e+08
C79: ໜີ້ | D79: ມີ | E79: ໜີ້ | F79: ມີ | G79: ໜີ້ | H79: ມີ | I79: Net profit
A80: 4102730 | B80: ຄ່າບໍລິການເຊົ່າລະບົບເທີມີນໍ່ LSX | C80: 21158280 | D80: 0 | E80: 21035391 | F80: 0 | G80: 42193671 | H80: 0 | I80: =+F80-E80 -> -21035391
A81: 4102731 | B81: ຄ່າບໍລິການເຊົ່າລະບົບດິດສເປຣເຢີ່ LSX | C81: 2566080 | D81: 0 | E81: 2551176 | F81: 0 | G81: 5117256 | H81: 0 | I81: =+F81-E81 -> -2551176
A82: 4108210 | B82: ຄ່າທຳນຽມທະນາຄານ ( ຈ່າຍ ) | C82: 369951.21 | D82: 0 | E82: 226048 | F82: 0 | G82: 595999.21 | H82: 0 | I82: =+F82-E82 -> -226048
A83: 4201100 | B83: ເງິນເດືອນພະນັກງານໃນການຈັດຕັ້ງ | C83: 159159677 | D83: 0 | E83: 156450000 | F83: 0 | G83: 315609677 | H83: 0 | I83: =+F83-E83 -> -156450000
A84: 4201400 | B84: ເງິນເພີ່ມໂມງ | C84: 47351378 | D84: 0 | E84: 2451289 | F84: 0 | G84: 49802667 | H84: 0 | I84: =+F84-E84 -> -2451289
A85: 4202200 | B85: ລາຍຈ່າຍຄ່າປະກັນໄພພະນັກງານ | C85: 10198798 | D85: 0 | E85: 9729001.1 | F85: 0 | G85: 19927800 | H85: 0 | I85: =+F85-E85 -> -9729001.1
A86: 4202220 | B86: ລາຍຈ່າຍຄ່ານ້ຳມັນລົດພະນັກງານ | C86: 17283871 | D86: 0 | E86: 16800000 | F86: 0 | G86: 34083871 | H86: 0 | I86: =+F86-E86 -> -16800000
A87: 4202800 | B87: ລາຍຈ່າຍສະຫວັດດີການພະນັກງານອື່ນໆ | C87: 14000000 | D87: 0 | E87: 0 | F87: 0 | G87: 14000000 | H87: 0 | I87: =+F87-E87 -> 0
A88: 4202811 | B88: ລາຍຈ່າຍເບ້ຍປະຊູມສະພາບໍລິຫານ | C88: 10736842 | D88: 0 | E88: 0 | F88: 0 | G88: 10736842 | H88: 0 | I88: =+F88-E88 -> 0
A89: 4203100 | B89: ສຳມະນາ ແລະຝຶກອົບຮົມພາຍໃນປະເທດ | C89: 5000000 | D89: 0 | E89: 0 | F89: 0 | G89: 5000000 | H89: 0 | I89: =+F89-E89 -> 0
A90: 4208300 | B90: ຄ່າໃຊ້ຈ່າຍໃນການຈັດກິດຈະກຳພະນັກງານ | C90: 0 | D90: 0 | E90: 500000 | F90: 0 | G90: 500000 | H90: 0 | I90: =+F90-E90 -> -500000
A91: 4208400 | B91: ຄ່າອາຫານຈັດປະຂູມພະນັກງານ | C91: 4087400 | D91: 0 | E91: 0 | F91: 0 | G91: 4087400 | H91: 0 | I91: =+F91-E91 -> 0
... A139: 5508400 | B139: ລາຍຮັບອື່ນໆ | C139: 0 | D139: 2000 | E139: 0 | F139: 1.2 | G139: 0 | H139: 2001.2 | I139: =+F139-E139 -> 1.2
B140: ລວມມູນຄ່າ | C140: =SUM(C80:C139) -> 6.4342647e+08 | D140: =SUM(D80:D139) -> 8.8734993e+08 | E140: =SUM(E80:E139) -> 7.9296976e+08 | F140: =SUM(F80:F139) -> 1.177315e+09 | G140: =SUM(G80:G139) -> 1.1942312e+09 | H140: =SUM(H80:H139) -> 1.8224998e+09 | I140: -5.859375e-05 | J140: 0 | K140: -3.90625e-05
A141: 1 | D141: =+D140-C140 -> 2.4392347e+08 | F141: =+F140-E140 -> 3.8434523e+08 | H141: =+H140-G140 -> 6.2826869e+08 | I141: =SUM(I80:I140) -> 3.8434523e+08

Sheet TB March'13
A1: ສາທາລະນະລັດ ປະຊາທິປະໄຕ ປະຊາຊົນລາວ | B1: ສັນຕິພາບ ເອກະລາດ ປະຊາທິປະໄຕ ເອກະພາບ ວັດທະນາຖາວອນ
D3: ໃບດູນດ່ຽງປະຈຳເດືອນ | E3: ເດືອນ 03/2013 | F3: ບໍລິສັດຫຼັກຊັບ ທຄຕລ-ກທ ຈຳກັດ_x000D_ ຊັ້ນ7, ຕຶກຕະຫຼາກຫຼັກຊັບລາວ, ຖະໜົນກຳແພງເມືອງ_x000D_ +856-21-265477+856-21-265488
C4: ໜີ້ | D4: ມີ | E4: ໜີ້ | F4: ມີ | G4: ໜີ້ | H4: ມີ | I4: Net profit
A5: 1101100 | B5: ເງິນສົດໃນຄັງ " HO " ກີບ | C5: 10000000 | D5: 0 | E5: 11551348 | F5: 11551348 | G5: 10000000 | H5: 0 | I5: =+G5-C5 -> 0 | J5: =+H5-D5 -> 0
A6: 1121110 | B6: ບັນຊີທຶນຈົດທະບຽນຂອງ ທຄຕລ-ກທ ຈຳກັດ ( ກີບ ) | C6: 2.2816035e+09 | D6: 0 | E6: 0 | F6: 0 | G6: 2.2816035e+09 | H6: 0 | I6: =+G6-C6 -> 0 | J6: =+H6-D6 -> 0
A7: 1131110 | B7: ບັນຊີກະແສລາຍວັນ ທຄຕລ: 010.0.11.00.24740 ( ກີບ ) | C7: 137607.24 | D7: 0 | E7: 0 | F7: 0 | G7: 137607.24 | H7: 0 | I7: =+G7-C7 -> 0 | J7: =+H7-D7 -> 0
A8: 1131111 | B8: ບັນຊີກະແສລາຍວັນ ທຄຕລ: 010.7.11.02.08233 ( ບາດ ) | C8: 1.3770871e+08 | D8: 0 | E8: 91415592 | F8: 1389351.2 | G8: 2.2773495e+08 | H8: 0 | I8: =+G8-C8 -> 90026240 | J8: =+H8-D8 -> 0
A9: 1131112 | B9: ບັນຊີກະແສລາຍວັນ ທຄຕລ: 010.9.11.01.19243 ( ໂດລ່າ ) | C9: 1528264.7 | D9: 0 | E9: 0 | F9: 27366.69 | G9: 1500898 | H9: 0 | I9: =+G9-C9 -> -27366.69 | J9: =+H9-D9 -> 0
A10: 1131113 | B10: ບັນຊີກະແສລາຍວັນ ທຄຕລ Proprietary AC: 010.4.19.00.00009 ( ກີບ ) | C10: 209470890 | D10: 0 | E10: 2847711383 | F10: 2886376382 | G10: 170805891 | H10: 0 | I10: =+G10-C10 -> -38664999 | J10: =+H10-D10 -> 0
A11: 1131115 | B11: ບັນຊີກະແສລາຍວັນ ທຄຕລ Aggregate AC: 010.4.19.00.00010 ( ກີບ ) | C11: 35835753400 | D11: 0 | E11: 6394665813 | F11: 11019585273 | G11: 31210833940 | H11: 0 | I11: =+G11-C11 -> -4624919460 | J11: =+H11-D11 -> 0
A12: 1131116 | B12: ບັນຊີກະແສລາຍວັນ ທຄຕລ for ETL staff IPO AC: 010.9.00.00001 ( ກີບ ) | C12: 100000 | D12: 0 | E12: 0 | F12: 0 | G12: 100000 | H12: 0 | I12: =+G12-C12 -> 0 | J12: =+H12-D12 -> 0
A13: 1131117 | B13: ບັນຊີກະແສລາຍວັນ ທຄຕລ ສຳລັບການຈອງ RO EDL-Gen :010.8.19.00.00012 LAk | C13: 0 | D13: 0 | E13: 0 | F13: 0 | G13: 0 | H13: 0 | I13: =+G13-C13 -> 0 | J13: =+H13-D13 -> 0
A14: 1131119 | B14: ບັນຊີກະແສລາຍວັນ ທຄຕລ ສຳລັບການ​ຈອງ PO EDL: 010.5.19.00.00013 Lak | C14: 3.8146973e-06 | D14: 0 | E14: 0 | F14: 0 | G14: 3.8146973e-06 | H14: 0 | I14: =+G14-C14 -> 0 | J14: =+H14-D14 -> 0
A15: 1131120 | B15: ບັນຊີກະແສລາຍວັນ ທຄຕລ ສຳລັບການ​ຈອງ PO EDL: 010.4.19.01.00006 USD | C15: 0 | D15: 1.3425946e-05 | E15: 0 | F15: 0 | G15: 0 | H15: 1.3425946e-05 | I15: =+G15-C15 -> 0 | J15: =+H15-D15 -> 0
A16: 1131121 | B16: ບັນຊີກະແສລາຍວັນ ເອຊີລີດາ 123359-1-1-101 | C16: 1000000 | D16: 0 | E16: 0 | F16: 0 | G16: 1000000 | H16: 0 | I16: =+G16-C16 -> 0 | J16: =+H16-D16 -> 0
A17: 1131130 | B17: ບັນຊີຝາກປະຢັດທີ່ ທຄຕລ: 013.2.12.00.00036 ກີບ | C17: 7.0766202e+09 | D17: 0 | E17: 2.2808393e+08 | F17: 4.8567068e+08 | G17: 6.8190335e+09 | H17: 0 | I17: =+G17-C17 -> -2.5758675e+08 | J17: =+H17-D17 -> 0 | L17: =+SUM(I5:I24) -> -4.4869567e+09 | M17: 1
A18: 1131131 | B18: ບັນຊີຝາກປະຢັດທີ່ ທຄຕລ: 013.9.12.01.00001 ( ໂດລ່າ ) | C18: 1.6945659e+08 | D18: 0 | E18: 246760.03 | F18: 70396783 | G18: 99306567 | H18: 0 | I18: =+G18-C18 -> -70150023 | J18: =+H18-D18 -> 0
A19: 1131134 | B19: ບັນຊີຝາກປະຢັດທີ່ ທສກ: 0402.0.00.220130 ( ກີບ ) | C19: 3808893026 | D19: 0 | E19: 153424658 | F19: 0 | G19: 3962317684 | H19: 0 | I19: =+G19-C19 -> 153424658 | J19: =+H19-D19 -> 0
A20: 1131137 | B20: ບັນຊີຝາກປະຍັດ ທຄຕລ-ກທ ທີ່ ເອຊີລີດາ 123359-1-0-0101 ( ກີບ ) | C20: 1.4076682e+09 | D20: 0 | E20: 2.6094098e+08 | F20: 0 | G20: 1.6686092e+09 | H20: 0 | I20: =+G20-C20 -> 2.6094098e+08 | J20: =+H20-D20 -> 0
A21: 1131153 | B21: ບັນຊີຝາກມີກຳນົດທີ່ ທສກ: 0402.0402.00.2131315.47.00000003 ( ກີບ ) | C21: 20000000000 | D21: 0 | E21: 0 | F21: 0 | G21: 20000000000 | H21: 0 | I21: =+G21-C21 -> 0 | J21: =+H21-D21 -> 0
A22: 1131154 | B22: ບັນຊີຝາກມີກຳນົດທີ່ ທສກ: 0402.0402.00.2131315.47.00000004 ( ກີບ ) | C22: 25000000000 | D22: 0 | E22: 0 | F22: 0 | G22: 25000000000 | H22: 0 | I22: =+G22-C22 -> 0 | J22: =+H22-D22 -> 0
A23: 1131159 | B23: ບັນຊີຝາກມີກຳນົດທີ່ ST Bank: 010.5.35.00.08899 ( ກີບ ) | C23: 5000000000 | D23: 0 | E23: 0 | F23: 0 | G23: 5000000000 | H23: 0 | I23: =+G23-C23 -> 0 | J23: =+H23-D23 -> 0
A24: 1131162 | B24: ບັນຊີເງິນຝາກມີກຳນົດ ທີ່ ທະນາຄານ ເອຊີລີດາ ( ກີບ ) | C24: 35000000000 | D24: 0 | E24: 0 | F24: 0 | G24: 35000000000 | H24: 0 | I24: =+G24-C24 -> 0 | J24: =+H24-D24 -> 0 | K24: =+SUM(I6:I24) -> -4.4869567e+09 | L24: =+K24+'Cash flow statement '!G20 -> 0
A25: 1137111 | B25: ດອກເບ້ຍຝາກມີກຳນົດ ຄ້າງຮັບ 1 ປີລົງມາ | C25: 6.0150114e+08 | D25: 0 | E25: 6.6170662e+08 | F25: 6.0150114e+08 | G25: 6.6170662e+08 | H25: 0 | I25: =+G25-C25 -> 60205479 | J25: =+H25-D25 -> 0
A26: 1138100 | B26: ກອງທຶນປົກປ້ອງຄວາມສ່ຽງໃນການຊຳລະສະສາງ | C26: 159699143 | D26: 0 | E26: 1161321 | F26: 0 | G26: 160860464 | H26: 0 | I26: =+G26-C26 -> 1161321 | J26: =+H26-D26 -> 0
A27: 1138810 | B27: ເງິນມັດຈຳຄ່າເຊົ່າ | C27: 11888910 | D27: 0 | E27: 0 | F27: 0 | G27: 11888910 | H27: 0 | I27: =+G27-C27 -> 0 | J27: =+H27-D27 -> 0 | L27: =-I25-I31 -> 7298891.9
A28: 1138830 | B28: ເງິນມັດຈຳອື່ນໆ | C28: 0 | D28: 0 | E28: 900898 | F28: 0 | G28: 900898 | H28: 0 | I28: =+G28-C28 -> 900898 | J28: =+H28-D28 -> 0
A29: 1201181 | B29: ລູກໜີ້ຊື້ຫຼັກຊັບຕາມຄຳສັ່ງຊື້-ບັນຊີເງິນສົດ | C29: 90243338 | D29: 0 | E29: 710154036 | F29: 800397374 | G29: 0 | H29: 0 | I29: =+G29-C29 -> -90243338 | J29: =+H29-D29 -> 0
A30: 1211110 | B30: ລູກໜີ້ບັນຊີຊື້-ຂາຍຫຼັກຊັບລະຫວ່າງບ/ສ ກັບ LSX | C30: 0 | D30: 0 | E30: 2606828749 | F30: 1847314009 | G30: 759514740 | H30: 0 | I30: =+G30-C30 -> 759514740 | J30: =+H30-D30 -> 0
A31: 1301720 | B31: ຄ່າທີ່ປຶກສາຄ້າງຮັບ | C31: 2.9469592e+08 | D31: 0 | E31: 69312147 | F31: 1.3681652e+08 | G31: 2.2719155e+08 | H31: 0 | I31: =+G31-C31 -> -67504371 | J31: =+H31-D31 -> 0
A32: 1302216 | B32: ເງິນລົງທືນຊົ່ວຄາວຫຼັກຊັບ-ເພື່ອຄ້າ-Port Trading | C32: 9.7325447e+08 | D32: 0 | E32: 278684380 | F32: 0 | G32: 1.2519388e+09 | H32: 0 | I32: =+G32-C32 -> 278684380 | J32: =+H32-D32 -> 0
A33: 1302218 | B33: ຄ່າປັບມູນຄ່າເງິນລົງທືນຊົ່ວຄາວຫຼັກຊັບ-ເພື່ອຄ້າ-Port trading | C33: 1.2994373e+08 | D33: 0 | E33: 1.1275875e+08 | F33: 1.2994373e+08 | G33: 1.1275875e+08 | H33: 0 | I33: =+G33-C33 -> -17184980 | J33: =+H33-D33 -> 0
A34: 1360000 | B34: ລູກໜີ້ອື່ນໆ | C34: 17950347 | D34: 0 | E34: 913950 | F34: 2895714 | G34: 15968583 | H34: 0 | I34: =+G34-C34 -> -1981764 | J34: =+H34-D34 -> 0
A35: 1361100 | B35: ອາກອນກຳໄລມອບລ່ວງໜ້າ | C35: 0 | D35: 0 | E35: 0 | F35: 0 | G35: 0 | H35: 0 | I35: =+G35-C35 -> 0 | J35: =+H35-D35 -> 0
A36: 1361300 | B36: ອາກອນອື່ນໆທີ່ຕ້ອງຮັບຄືນ | C36: 0 | D36: 0 | E36: 372200 | F36: 0 | G36: 372200 | H36: 0 | I36: =+G36-C36 -> 372200 | J36: =+H36-D36 -> 0
A37: 1362100 | B37: ເງິນຈ່າຍລ່ວງໜ້າເພື່ອເຄື່ອນໄຫວວຽກງານ | C37: 1955000 | D37: 0 | E37: 10000000 | F37: 7955000 | G37: 4000000 | H37: 0 | I37: =+G37-C37 -> 2045000 | J37: =+H37-D37 -> 0
A38: 1388110 | B38: ຄ່າເຊົ່າຈ່າຍລ່ວງໜ້າ | C38: 3.4188912e+08 | D38: 0 | E38: 51041361 | F38: 52260410 | G38: 3.4067007e+08 | H38: 0 | I38: =+G38-C38 -> -1219048.5 | J38: =+H38-D38 -> 0
A39: 1388120 | B39: ຄ່າປະກັນໄພຈ່າຍລ່ວງໜ້າ | C39: 1.1851435e+08 | D39: 0 | E39: 0 | F39: 12019417 | G39: 1.0649493e+08 | H39: 0 | I39: =+G39-C39 -> -12019417 | J39: =+H39-D39 -> 0
A40: 1388170 | B40: ຄ່າໜັງສືພີມ ຈ່າຍລ່ວງໜ້າອື່ນໆ | C40: 4642871 | D40: 0 | E40: 0 | F40: 448438.36 | G40: 4194432.6 | H40: 0 | I40: =+G40-C40 -> -448438.36 | J40: =+H40-D40 -> 0
A41: 1388180 | B41: ລາຍຈ່າຍ ຈ່າຍລ່ວງໜ້າອື່ນໆ | C41: 3988600 | D41: 0 | E41: 0 | F41: 846894.52 | G41: 3141705.5 | H41: 0 | I41: =+G41-C41 -> -846894.52 | J41: =+H41-D41 -> 0 | L41: =+SUM(I6:I41) -> -3.575521e+09
...

Sheet TB June'13
A1: ສາທາລະນະລັດ ປະຊາທິປະໄຕ ປະຊາຊົນລາວ | B1: ສັນຕິພາບ ເອກະລາດ ປະຊາທິປະໄຕ ເອກະພາບ ວັດທະນາຖາວອນ
D3: ໃບດູນດ່ຽງປະຈຳເດືອນ | E3: ເດືອນ 06/2013 | F3: ບໍລິສັດຫຼັກຊັບ ທຄຕລ-ກທ ຈຳກັດ_x000D_ ຊັ້ນ7, ຕຶກຕະຫຼາກຫຼັກຊັບລາວ, ຖະໜົນກຳແພງເມືອງ_x000D_ +856-21-265477+856-21-265488
C4: ໜີ້ | D4: ມີ | E4: ໜີ້ | F4: ມີ | G4: ໜີ້ | H4: ມີ
A5: 1101100 | B5: ເງິນສົດໃນຄັງ " HO " ກີບ | C5: 10000000 | D5: 0 | E5: 15990718 | F5: 15990718 | G5: 10000000 | H5: 0 | I5: =+G5-C5 -> 0 | J5: =+H5-D5 -> 0
A6: 1121110 | B6: ບັນຊີທຶນຈົດທະບຽນຂອງ ທຄຕລ-ກທ ຈຳກັດ ( ກີບ ) | C6: 2.2816035e+09 | D6: 0 | E6: 0 | F6: 0 | G6: 2.2816035e+09 | H6: 0 | I6: =+G6-C6 -> 0 | J6: =+H6-D6 -> 0
A7: 1131110 | B7: ບັນຊີກະແສລາຍວັນ ທຄຕລ: 010.0.11.00.24740 ( ກີບ ) | C7: 137607.24 | D7: 0 | E7: 0 | F7: 20000 | G7: 117607.24 | H7: 0 | I7: =+G7-C7 -> -20000 | J7: =+H7-D7 -> 0
A8: 1131111 | B8: ບັນຊີກະແສລາຍວັນ ທຄຕລ: 010.7.11.02.08233 ( ບາດ ) | C8: 2.6401201e+08 | D8: 0 | E8: 0 | F8: 2.5585843e+08 | G8: 8153586.4 | H8: 0 | I8: =+G8-C8 -> -2.5585843e+08 | J8: =+H8-D8 -> 0
A9: 1131112 | B9: ບັນຊີກະແສລາຍວັນ ທຄຕລ: 010.9.11.01.19243 ( ໂດລ່າ ) | C9: 1488864.4 | D9: 0 | E9: 15333.11 | F9: 15500 | G9: 1488697.5 | H9: 0 | I9: =+G9-C9 -> -166.89 | J9: =+H9-D9 -> 0
A10: 1131113 | B10: ບັນຊີກະແສລາຍວັນ ທຄຕລ Proprietary AC: 010.4.19.00.00009 ( ກີບ ) | C10: 129974887 | D10: 0 | E10: 237694712 | F10: 300288018 | G10: 67381581 | H10: 0 | I10: =+G10-C10 -> -62593306 | J10: =+H10-D10 -> 0
A11: 1131115 | B11: ບັນຊີກະແສລາຍວັນ ທຄຕລ Aggregate AC: 010.4.19.00.00010 ( ກີບ ) | C11: 37956098685 | D11: 0 | E11: 2998047564 | F11: 6396092184 | G11: 34558054065 | H11: 0 | I11: =+G11-C11 -> -3398044620 | J11: =+H11-D11 -> 0
A12: 1131116 | B12: ບັນຊີກະແສລາຍວັນ ທຄຕລ for ETL staff IPO AC: 010.9.00.00001 ( ກີບ ) | C12: 100000 | D12: 0 | E12: 0 | F12: 0 | G12: 100000 | H12: 0 | I12: =+G12-C12 -> 0 | J12: =+H12-D12 -> 0
A13: 1131117 | B13: ບັນຊີກະແສລາຍວັນ ທຄຕລ ສຳລັບການຈອງ RO EDL-Gen :010.8.19.00.00012 LAk | C13: 0 | D13: 0 | E13: 0 | F13: 0 | G13: 0 | H13: 0 | I13: =+G13-C13 -> 0 | J13: =+H13-D13 -> 0
A14: 1131119 | B14: ບັນຊີກະແສລາຍວັນ ທຄຕລ ສຳລັບການ​ຈອງ PO EDL: 010.5.19.00.00013 Lak | C14: 3.8146973e-06 | D14: 0 | E14: 0 | F14: 0 | G14: 3.8146973e-06 | H14: 0 | I14: =+G14-C14 -> 0 | J14: =+H14-D14 -> 0
A15: 1131120 | B15: ບັນຊີກະແສລາຍວັນ ທຄຕລ ສຳລັບການ​ຈອງ PO EDL: 010.4.19.01.00006 USD | C15: 0 | D15: 1.3425946e-05 | E15: 0 | F15: 0 | G15: 0 | H15: 1.3425946e-05 | I15: =+G15-C15 -> 0 | J15: =+H15-D15 -> 0
A16: 1131121 | B16: ບັນຊີກະແສລາຍວັນ ເອຊີລີດາ 123359-1-1-101 | C16: 1000000 | D16: 0 | E16: 0 | F16: 0 | G16: 1000000 | H16: 0 | I16: =+G16-C16 -> 0 | J16: =+H16-D16 -> 0
... A28: 1138810 | B28: ເງິນມັດຈຳຄ່າເຊົ່າ | C28: 11888910 | D28: 0 | E28: 0 | F28: 0 | G28: 11888910 | H28: 0 | I28: =+G28-C28 -> 0 | J28: =+H28-D28 -> 0
A29: 1138830 | B29: ເງິນມັດຈຳອື່ນໆ | C29: 0 | D29: 0 | E29: 0 | F29: 0 | G29: 0 | H29: 0 | I29: =+G29-C29 -> 0 | J29: =+H29-D29 -> 0 | L29: =+SUM(I27:I29)+SUM(I35:I42) -> 2.5312468e+08
A30: 1201181 | B30: ລູກໜີ້ຊື້ຫຼັກຊັບຕາມຄຳສັ່ງຊື້-ບັນຊີເງິນສົດ | C30: 0 | D30: 0 | E30: 79527050 | F30: 69761435 | G30: 9765615 | H30: 0 | I30: =+G30-C30 -> 9765615 | J30: =+H30-D30 -> 0
A31: 1211110 | B31: ລູກໜີ້ບັນຊີຊື້-ຂາຍຫຼັກຊັບລະຫວ່າງບ/ສ ກັບ LSX | C31: 74092454 | D31: 0 | E31: 157466113 | F31: 167933277 | G31: 63625290 | H31: 0 | I31: =+G31-C31 -> -10467164 | J31: =+H31-D31 -> 0
A32: 1301720 | B32: ຄ່າທີ່ປຶກສາຄ້າງຮັບ | C32: 1.1920929e-07 | D32: 0 | E32: 0 | F32: 0 | G32: 1.1920929e-07 | H32: 0 | I32: =+G32-C32 -> 0 | J32: =+H32-D32 -> 0
A33: 1302216 | B33: ເງິນລົງທືນຊົ່ວຄາວຫຼັກຊັບ-ເພື່ອຄ້າ-Port Trading | C33: 1.4593232e+09 | D33: 0 | E33: 2.0306113e+08 | F33: 0 | G33: 1.6623843e+09 | H33: 0 | I33: =+G33-C33 -> 2.0306113e+08 | J33: =+H33-D33 -> 0
A34: 1302218 | B34: ຄ່າປັບມູນຄ່າເງິນລົງທືນຊົ່ວຄາວຫຼັກຊັບ-ເພື່ອຄ້າ-Port trading | C34: 32840178 | D34: 0 | E34: 27401751 | F34: 32840178 | G34: 27401751 | H34: 0 | I34: =+G34-C34 -> -5438427.2 | J34: =+H34-D34 -> 0
A35: 1360000 | B35: ລູກໜີ້ອື່ນໆ | C35: 15444583 | D35: 0 | E35: 1662732 | F35: 2246732 | G35: 14860583 | H35: 0 | I35: =+G35-C35 -> -584000 | J35: =+H35-D35 -> 0
A36: 1361100 | B36: ອາກອນກຳໄລມອບລ່ວງໜ້າ | C36: 5862058 | D36: 0 | E36: 427322763 | F36: 120995945 | G36: 312188876 | H36: 0 | I36: =+G36-C36 -> 306326818 | J36: =+H36-D36 -> 0
A37: 1361300 | B37: ອາກອນອື່ນໆທີ່ຕ້ອງຮັບຄືນ | C37: 0 | D37: 0 | E37: 0 | F37: 0 | G37: 0 | H37: 0 | I37: =+G37-C37 -> 0 | J37: =+H37-D37 -> 0
A38: 1362100 | B38: ເງິນຈ່າຍລ່ວງໜ້າເພື່ອເຄື່ອນໄຫວວຽກງານ | C38: 7000000 | D38: 0 | E38: 12000000 | F38: 12000000 | G38: 7000000 | H38: 0 | I38: =+G38-C38 -> 0 | J38: =+H38-D38 -> 0
A39: 1388110 | B39: ຄ່າເຊົ່າຈ່າຍລ່ວງໜ້າ | C39: 2.3982322e+08 | D39: 0 | E39: 0 | F39: 40644464 | G39: 1.9917876e+08 | H39: 0 | I39: =+G39-C39 -> -40644464 | J39: =+H39-D39 -> 0
A40: 1388120 | B40: ຄ່າປະກັນໄພຈ່າຍລ່ວງໜ້າ | C40: 82843824 | D40: 0 | E40: 0 | F40: 11631694 | G40: 71212131 | H40: 0 | I40: =+G40-C40 -> -11631694 | J40: =+H40-D40 -> 0
A41: 1388170 | B41: ຄ່າໜັງສືພີມ ຈ່າຍລ່ວງໜ້າອື່ນໆ | C41: 3312021.7 | D41: 0 | E41: 0 | F41: 433972.6 | G41: 2878049.1 | H41: 0 | I41: =+G41-C41 -> -433972.6 | J41: =+H41-D41 -> 0
A42: 1388180 | B42: ລາຍຈ່າຍ ຈ່າຍລ່ວງໜ້າອື່ນໆ | C42: 1475235.6 | D42: 0 | E42: 0 | F42: 819575.34 | G42: 655660.29 | H42: 0 | I42: =+G42-C42 -> -819575.34 | J42: =+H42-D42 -> 0 | L42: =-SUM(I27:I29)-SUM(I35:I42) -> -2.5312468e+08
A43: 1441810 | B43: ຊັອບແວຄອມພີວເຕີ່ | C43: 3.0087805e+08 | D43: 0 | E43: 0 | F43: 0 | G43: 3.0087805e+08 | H43: 0 | I43: =+G43-C43 -> 0 | J43: =+H43-D43 -> 0
A44: 1442400 | B44: ພາຫະນະຂົນສົ່ງ | C44: 629368000 | D44: 0 | E44: 0 | F44: 0 | G44: 629368000 | H44: 0 | I44: =+G44-C44 -> 0 | J44: =+H44-D44 -> 0
A45: 1442510 | B45: ຄ່າຕົບແຕ່ງສຳນັກງານ | C45: 1.5525121e+09 | D45: 0 | E45: 0 | F45: 0 | G45: 1.5525121e+09 | H45: 0 | I45: =+G45-C45 -> 0 | J45: =+H45-D45 -> 0
A46: 1442610 | B46: ອຸປະກອນຄອມພີວເຕີ່ | C46: 6.4967738e+08 | D46: 0 | E46: 4174500 | F46: 0 | G46: 6.5385188e+08 | H46: 0 | I46: =+G46-C46 -> 4174500 | J46: =+H46-D46 -> 0
A47: 1442710 | B47: ອຸປະກອນສຳນັກງານ | C47: 1.4222659e+08 | D47: 0 | E47: 0 | F47: 980000 | G47: 1.4124659e+08 | H47: 0 | I47: =+G47-C47 -> -980000 | J47: =+H47-D47 -> 0 | L47: =+SUM(I6:I48) -> -2.8455956e+09
A48: 1442720 | B48: ອຸປະກອນເຟີນີເຈີ່ | C48: 3.8108966e+08 | D48: 0 | E48: 0 | F48: 0 | G48: 3.8108966e+08 | H48: 0 | I48: =+G48-C48 -> 0 | J48: =+H48-D48 -> 0
A49: 1481181 | B49: ຄ່າຕັດຈຳໜ່າຍຄອມພີວເຕີ່ຊ້ອບແວສະສົມ | C49: 0 | D49: 77422229 | E49: 0 | F49: 4943231.9 | G49: 0 | H49: 82365461 | I49: =+G49-C49 -> 0 | J49: =+H49-D49 -> 4943231.9
A50: 1481240 | B50: ຄ່າຫຼຸ່ຍຫ້ຽນສະສົມພາຫະນະ | C50: 0 | D50: 2.9623562e+08 | E50: 0 | F50: 10337898 | G50: 0 | H50: 3.0657352e+08 | I50: =+G50-C50 -> 0 | J50: =+H50-D50 -> 10337898
A51: 1481251 | B51: ຄ່າຫຼຸ່ຍຫ້ຽນສະສົມ ຄ່າຕົບແຕ່ງສຳນັກງານ | C51: 0 | D51: 3.7056837e+08 | E51: 0 | F51: 12749915 | G51: 0 | H51: 3.8331829e+08 | I51: =+G51-C51 -> 0 | J51: =+H51-D51 -> 12749915
A52: 1481261 | B52: ຄ່າຫຼຸ່ຍຫ້ຽນສະສົມ ອຸປະກອນຄອມພີວເຕີ່ | C52: 0 | D52: 1.3855418e+08 | E52: 0 | F52: 5371098.3 | G52: 0 | H52: 1.4392528e+08 | I52: =+G52-C52 -> 0 | J52: =+H52-D52 -> 5371098.3
...

Sheet BS
A1: ສາທາລະນະລັດ ປະຊາທິປະໄຕ ປະຊາຊົນລາວ | B1: ສັນຕິພາບ ເອກະລາດ ປະຊາທິປະໄຕ ເອກະພາບ ວັດທະນາຖາວອນ
A2: ບໍລິສັດຫຼັກຊັບ ທຄຕລ-ກທ ຈຳກັດ_x000D_ ຊັ້ນ7, ຕຶກຕະຫຼາກຫຼັກຊັບລາວ, ຖະໜົນກຳແພງເມືອງ_x000D_ +856-21-265477+856-21-265488
D3: ໃບສະຫລຸບຊັບສົມບັດ | E3: ໃນປີ 2012
A4: ລ/ດ | B4: ເລກບັນຊີ | C4: ເນື້ອໃນລາຍການ | D4: ປີນີ້ | E4: ປີກ່ອນ
A5: 1 | B5: 1. ​ເງິນສົດ ​ແລະ ທຽບ​ເທົ່​າເງິນສົດ | D5: 4468000 | E5: 10000000
A6: 1 | B6: 1101100 | C6: ເງິນສົດໃນຄັງ " HO " ກີບ | D6: 4468000 | E6: 10000000
A7: 2 | B7: 2.1. ເງິນຝາກທະນາຄານ | D7: 1.5681483e+11 | E7: 1.3662937e+11
A8: 2 | B8: 1131115 | C8: ບັນຊີກະແສລາຍວັນ ທຄຕລ Aggregate AC: 010.4.19.00.00010 ( ກີບ ) | D8: 55650947823 | E8: 39741098167
A9: 3 | B9: 1131116 | C9: ບັນຊີກະແສລາຍວັນ ທຄຕລ for ETL staff IPO AC: 010.9.00.00001 ( ກີບ ) | D9: 100000 | E9: 100000
A10: 4 | B10: 1131154 | C10: ບັນຊີຝາກມີກຳນົດທີ່ ທສກ: 0402.0402.00.2131315.47.00000004 ( ກີບ ) | D10: 25000000000 | E10: 0
B11: 1131110 | C11: ບັນຊີກະແສລາຍວັນ ທຄຕລ: 010.0.11.00.24740 ( ກີບ ) | D11: 137607.24 | E11: 652607.74
A12: 6 | B12: 1131159 | C12: ບັນຊີຝາກມີກຳນົດທີ່ ST Bank: 010.5.35.00.08899 ( ກີບ ) | D12: 5000000000 | E12: 0
A13: 7 | B13: 1131113 | C13: ບັນຊີກະແສລາຍວັນ ທຄຕລ Proprietary AC: 010.4.19.00.00009 ( ກີບ ) | D13: 294629790 | E13: 92595445
A14: 8 | B14: 1131162 | C14: ບັນຊີເງິນຝາກມີກຳນົດ ທີ່ ທະນາຄານ ເອຊີລີດາ ( ກີບ ) | D14: 35000000000 | E14: 0
A15: 9 | B15: 1131111 | C15: ບັນຊີກະແສລາຍວັນ ທຄຕລ: 010.7.11.02.08233 ( ບາດ ) | D15: 1788525.4 | E15: 713249.55
A16: 10 | B16: 1131134 | C16: ບັນຊີຝາກປະຢັດທີ່ ທສກ: 0402.0.00.220130 ( ກີບ ) | D16: 3469166998 | E16: 1358879432
A17: 11 | B17: 1131131 | C17: ບັນຊີຝາກປະຢັດທີ່ ທຄຕລ: 013.9.12.01.00001 ( ໂດລ່າ ) | D17: 30012667 | E17: 8.9027339e+08
A18: 12 | B18: 1121110 | C18: ບັນຊີທຶນຈົດທະບຽນຂອງ ທຄຕລ-ກທ ຈຳກັດ ( ກີບ ) | D18: 2.2816035e+09 | E18: 7.2281614e+10
A19: 13 | B19: 1131112 | C19: ບັນຊີກະແສລາຍວັນ ທຄຕລ: 010.9.11.01.19243 ( ໂດລ່າ ) | D19: 1594317.1 | E19: 1641620.4
A20: 14 | B20: 1131121 | C20: ບັນຊີກະແສລາຍວັນ ເອຊີລີດາ 123359-1-1-101 | D20: 1000000 | E20: 0
A21: 15 | B21: 1131153 | C21: ບັນຊີຝາກມີກຳນົດທີ່ ທສກ: 0402.0402.00.2131315.47.00000003 ( ກີບ ) | D21: 20000000000 | E21: 20000000000
A22: 16 | B22: 1131130 | C22: ບັນຊີຝາກປະຢັດທີ່ ທຄຕລ: 013.2.12.00.00036 ກີບ | D22: 9.2493495e+09 | E22: 2.2618014e+09
A23: 17 | B23: 1131137 | C23: ບັນຊີຝາກປະຍັດ ທຄຕລ-ກທ ທີ່ ເອຊີລີດາ 123359-1-0-0101 ( ກີບ ) | D23: 8.3449851e+08 | E23: 0
A24: 3 | B24: 3.1. ເງິນລົງທຶນໄລຍະສັ້ນ | D24: 5.149202e+08 | E24: 79930000
A25: 18 | B25: 1302216 | C25: ເງິນລົງທືນຊົ່ວຄາວຫຼັກຊັບ-ເພື່ອຄ້າ-Port Trading | D25: 4.7421994e+08 | E25: 117180970
A26: 19 | B26: 1302218 | C26: ຄ່າປັບມູນຄ່າເງິນລົງທືນຊົ່ວຄາວຫຼັກຊັບ-ເພື່ອຄ້າ-Port trading | D26: 40700260 | E26: -37250970
A27: 4 | B27: 4.1. ໜີ້ຕ້ອງ​ຮັບ​ທາງການຄ້າ | D27: 58820889 | E27: 4284683
A28: 20 | B28: 1201181 | C28: ລູກໜີ້ຊື້ຫຼັກຊັບຕາມຄຳສັ່ງຊື້-ບັນຊີເງິນສົດ | D28: 58820889 | E28: 4284683
A29: 5 | B29: 4.3. ໜີ້ຕ້ອງ​ຮັບ​ລະຫວ່າງ​ບໍລິສັດໃນກຸ່ມ | C29: 0 | D29: 23823233
A30: 21 | B30: 1211110 | C30: ລູກໜີ້ບັນຊີຊື້-ຂາຍຫຼັກຊັບລະຫວ່າງບ/ສ ກັບ LSX | D30: 0 | E30: 23823233
A31: 6 | B31: 6. ຊັບສິນໝູນວຽນອື່ນໆ | D31: 6468583 | E31: 1.526439e+08
A32: 22 | B32: 1360000 | C32: ລູກໜີ້ອື່ນໆ | D32: 5968583 | E32: 61100181
A33: 23 | B33: 1361300 | C33: ອາກອນອື່ນໆທີ່ຕ້ອງຮັບຄືນ | D33: -7.4505806e-09 | E33: 27382364
A34: 24 | B34: 1362100 | C34: ເງິນຈ່າຍລ່ວງໜ້າເພື່ອເຄື່ອນໄຫວວຽກງານ | D34: 500000 | E34: 36400000
A35: 25 | B35: 1361100 | C35: ອາກອນກຳໄລມອບລ່ວງໜ້າ | D35: 0 | E35: 27761356
A36: 7 | B36: 2. ຊັບສິນຄົງທີ່ບໍ່ມີຕົວຕົນ | D36: 3.0777805e+08 | E36: 2.7021397e+08
A37: 26 | B37: 1441810 | C37: ຊັອບແວຄອມພີວເຕີ່ | D37: 3.0777805e+08 | E37: 2.7021397e+08
A38: 8 | B38: 3. ຊັບ​ສົມບັດຄົງ​ທີ່​ມີຕົວຕົນ | D38: 3.3460869e+09 | E38: 3.1995897e+09
A39: 27 | B39: 1442510 | C39: ຄ່າຕົບແຕ່ງສຳນັກງານ | D39: 1.5476721e+09 | E39: 1.5394821e+09
A40: 28 | B40: 1442400 | C40: ພາຫະນະຂົນສົ່ງ | D40: 629368000 | E40: 615368000
...

Sheet PL
A1: ສາທາລະນະລັດ ປະຊາທິປະໄຕ ປະຊາຊົນລາວ | B1: ສັນຕິພາບ ເອກະລາດ ປະຊາທິປະໄຕ ເອກະພາບ ວັດທະນາຖາວອນ
A2: ບໍລິສັດຫຼັກຊັບ ທຄຕລ-ກທ ຈຳກັດ_x000D_ ຊັ້ນ7, ຕຶກຕະຫຼາກຫຼັກຊັບລາວ, ຖະໜົນກຳແພງເມືອງ_x000D_ +856-21-265477+856-21-265488
D3: ໃບລາຍງານຜົນໄດ້ຮັບ | E3: ໃນປີ 2012
A4: ເອກະສານຊ້ອນທ້າຍ
A5: ລຳດັບ | B5: ລາຍຮັບ | C5: 1.1 | D5: 0 | E5: 0
A6: I | B6: ລາຍຮັບຈາກການດຳເນີນງານ | C6: 1.1.1 | D6: 5.4220711e+10 | E6: 0
B7: 1. ຄ່ານາຍໜ້າຈາກການຊື້-ຂາຍຫຼັກຊັບ | C7: 1.1.1.1 | D7: 1698263965 | E7: 0
B8: 2. ຄ່າບໍລິການ | C8: 1.1.1.2 | D8: 4.7128415e+10 | E8: 0
B9: 2.1. ຄ່າບໍລິການໃຫ້ຄຳປຶກສາທາງດ້ານການເງິນ | C9: 1.1.1.2.1 | D9: 4.3376696e+09 | E9: 0
B10: 2.2. ຄ່າບໍລິການ ຄໍ້າປະກັນການຈັດຈຳໜ່າຍຫຼັກຊັບ | C10: 1.1.1.2.2 | D10: 42790745204 | E10: 0
B11: 2.3. ຄ່າບໍລິການ ເປັນຕົວແທນຈຳໝ່າຍຫຼັກຊັບ | C11: 1.1.1.2.3 | D11: 0 | E11: 0
B12: 3. ກຳໄລ(ຂາດທຶນ)ຈາກການຊື້ຂາຍຫຼັກຊັບ | C12: 1.1.1.3 | D12: 74367920 | E12: 0
B13: 4. ດອກເບ້ຍ ແລະ ເງິນປັນຜົນ | C13: 1.1.1.4 | D13: 5.3196641e+09 | E13: 0
A14: II | B14: ລາຍຮັບອື່ນໆ | C14: 1.1.2 | D14: -1.4064442e+08 | E14: 0
B15: ລາຍຮັບອື່ນໆ | C15: 1.1.2.5 | D15: -1.4064442e+08 | E15: 0
B16: ລວມຍອດລາຍຮັບ | C16: 1.13 | D16: 5.4080066e+10 | E16: 0
A17: ລຳດັບ | B17: ລາຍຈ່າຍ | C17: 1.2. | D17: 0 | E17: 0
A18: I | B18: ລາຍຈ່າຍຈາກການດຳເນີນງານ | C18: 1.2.1 | D18: 4.2748984e+10 | E18: 0
B19: 1. ລາຍຈ່າຍຄ່ານາຍໜ້າຊື້-ຂາຍຫຼັກຊັບ | C19: 1.2.1.1.1 | D19: 1.0378224e+09 | E19: 0
B20: 2. ລາຍຈ່າຍຄ່າໃຫ້ຄຳປຶກສາທາງການເງິນ | C20: 1.2.1.1.2 | D20: 4.1056803e+10 | E20: 0
B21: 3. ລາຍຈ່າຍຄ່າໃຫ້ການຄໍ້າປະກັນການຈັດຈຳໜ່າຍຫຼັກຊັບ | C21: 1.2.1.1.3 | D21: 0 | E21: 0
B22: 4. ລາຍຈ່າຍການຄ້າຫຼັກຊັບ | C22: 1.2.1.1.4 | D22: 0 | E22: 0
B23: 5. ລາຍຈ່າຍອື່ນໆທາງດ້ານຫຼັກຊັບ | C23: 1.2.1.1.5 | D23: 6.5435877e+08 | E23: 0
A24: II | B24: ລາຍຈ່າຍໃນການບໍລິຫານ | C24: 1.2.2 | D24: 6.0327915e+09 | E24: 0
B25: 1. ລາຍຈ່າຍກ່ຽວກັບພະນັກງານ | C25: 1.2.2.2.1 | D25: 3.3459934e+09 | E25: 0
B26: 2. ຄ່າຫລຸ້ຍຫ້ຽນອາຄານສະຖານທີ່ ແລະ ອຸປະກອນ | C26: 1.2.2.2.2 | D26: 4.3048138e+08 | E26: 0
B27: 3. ລາຍຈ່າຍພາສີອາກອນ | C27: 1.2.2.2.3 | D27: 77870728 | E27: 0
B28: 4. ລາຍຈ່າຍອື່ນໆ | C28: 1.2.2.2.4 | D28: 2.178446e+09 | E28: 0
A29: III | B29: ລາຍຈ່າຍດອກເບ້ຍເງິນກູ້ຢືມ | C29: 1.2.3 | D29: 0 | E29: 0
B30: ລາຍຈ່າຍດອກເບ້ຍເງິນກູ້ຢືມ | C30: 1.2.3.3.1 | D30: 0 | E30: 0
B31: ລວມຍອດລາຍຈ່າຍ | C31: 1.2.4 | D31: 4.8781776e+10 | E31: 0
B32: ກຳໄລກ່ອນອາກອນ | C32: 1.2.4.1 | D32: 5.2982905e+09 | E32: 0
B33: ອາກອນກຳໄລ | C33: 1.2.4.2 | D33: 1.534075e+09 | E33: 0
B34: ກຳໄລສຸດທິ | C34: 1.2.4.3 | D34: 3.7642156e+09 | E34: 0
A35: ນະຄອນຫຼວງວຽງຈັນ ວັນທີ : ......../......../............ , | B35: ຜູ້ອຳນວຍການ | C35: ທີ່ປຶກສາບັນຊີ | D35: ພະນັກງານບັນຊີ | E35: ຜູ້ສັງລວມ | F35: ............…………………...... | G35: ............…………………...... | H35: ............…………………...... | I35: ............…………………...... | J35: ...………………………….. | K35: ...………………………….. | L35: ...………………………….. | M35: ...…………………………..
A36: 1

Sheet TB Q I 2013
A1: ສາທາລະນະລັດ ປະຊາທິປະໄຕ ປະຊາຊົນລາວ | B1: ສັນຕິພາບ ເອກະລາດ ປະຊາທິປະໄຕ ເອກະພາບ ວັດທະນາຖາວອນ | D1: TB for Quarter
C3: Openning | E3: Movement | G3: Balance
C4: ໜີ້ | D4: ມີ | E4: ໜີ້ | F4: ມີ | G4: ໜີ້ | H4: ມີ
